Workbook

Sheet 揽收业务网点
A1: 有揽收业务的网点
A2: CGCM -CE | B2: CE
A3: DC MVF-RN | B3: CE
A4: F GYN 02-GO | B4: GP
A5: F APG - GO | B5: GP
A6: F RFI-DF | B6: GP
A7: F TRD-GO | B7: GP
A8: F PLN-DF | B8: GP
A9: PA MELI-SMR-SP | B9: SPS
A10: PA MELI-BRE-SP | B10: SPS
A11: PA VIA-SP | B11: SPS
A12: PA MANDAE-SP | B12: SPS
A13: PA SATELITAL-SP | B13: SPS
... A163: DC CDG-RJ | B163: RJ

Sheet 同场线路Rotas do mesmo SC
A1: 线路Rota
A2: H30-H235-0800-1
A3: H235-H30-0900-1
A4: H104-H204-0800-1
A5: H204-H104-1400-1
A6: S341-S402-0700-1
A7: S417-S401-0700-1
A8: S234-BRE-1800-1
A9: S414-S408-0700-1
A10: S175-S417-1800-1
A11: S175-S417-2000-2
A12: S061-BRE-2200-2
... A121: FEC-E362-0350-1

Sheet 支线运输综合报表
A1: Número do ID | B1: Status | C1: Nome da viagem | D1: Tipo de viagem | E1: Tipo de linha | F1: Saída do dia | G1: Quilometragem | H1: Placa do carro | I1: Modelo do veículo | J1: Nome completo do transportador | K1: Tipo de transportador | L1: Abreviatura de transportador | M1: Condutor | N1: Telefone do carro | O1: Código de estação de partida | P1: Nome de estação de partida | Q1: Regional de saída do carro | R1: Quantidade de encomendas escaneadas | S1: Número de " Pedido mãe" | T1: Tempo de início do carregamento | U1: Tempo de término do carregamento | V1: Tempo de carregamento (min) | W1: Horario de carregamento passou das 20:00 hs? | X1: hora de lacre | Y1: Tempo de partida planejada | Z1: Horário real de saída | AA1: Horário de check-out do codutor | AB1: Código de estação de chegada | AC1: Nome de estação de chegada | AD1: Regional de chegada do carro | AE1: Tempo de chegada planejado | AF1: Tempo real de chegada | AG1: Duração de atraso (min) | AH1: Horário de check-in do motorista | AI1: hora de deslacre | AJ1: Tempo de espera entre o check-in até o início do descarregamento (min) | AK1: Tempo de início de descarga | AL1: Tempo de término de descarga | AM1: Tempo de descarregamento (min) | AN1: Lacramento | AO1: Deslacramento | AP1: Chegada planejada | AQ1: Transferencia do mesmo SC, não necessita de caminhão | AR1: Determine o Ponto de Retira
A2: 任务单号 | B2: 任务状态Concluído | C2: 任务名称 | D2: 业务属性 | E2: 线路类型 | F2: 班次 | G2: 里程 | H2: 车牌号 | I2: 车型名称 | J2: 承运商全称 | K2: 承运商类型 | L2: 承运商简称 | M2: 司机 | N2: 随车电话 | O2: 发车网点编码 | P2: 发车网点名称 | Q2: 发车所属代理区 | R2: 装车扫描数量 | S2: 主单数量 | T2: 装车开始时间 | U2: 装车结束时间 | V2: 装车时长（min） | W2: 装车是否超过20H | X2: 封车时间 | Y2: 计划发车时间 | Z2: 实际发车时间 | AA2: 司机签出时间 | AB2: 到车网点编码 | AC2: 到车网点名称 | AD2: 到车所属代理区 | AE2: 计划到达时间 | AF2: 实际到达时间 | AG2: 迟到时长（min） | AH2: 司机打卡时间 | AI2: 解车时间 | AJ2: 卸车排队时长（min） | AK2: 卸车开始时间 | AL2: 卸车结束时间 | AM2: 卸车时长（min） | AN2: 封车Lacre | AO2: 解封Deslacre | AP2: 计划到达 | AQ2: 同场线路 | AR2: 判断揽收网点
A3: SRTR22605666051 | B3: Concluído：已完成 | C3: MAO1-C610-0700-1 | D3: Horário padrão | E3: Entrega | F3: 1 | G3: 500 | H3: JWP3563 | I3: 3/4 | J3: DARLISSON DANIEL MARQUES SOUSA | K3: Transportadora-三方 | L3: DARLISSON | M3: DARLISSON DANIEL MARQUES SOUSA | N3: 92985204417 | O3: 89202 | P3: DC MAO-AM | Q3: GP | R3: 409 | S3: 273 | T3: 2026-09-28 07:05:11 | U3: 2026-09-28 07:05:14 | V3: 1 | W3: Não | X3: 2026-09-28 07:05:36 | Y3: 2026-09-28 07:00:00 | Z3: 2026-09-28 07:05:36 | AA3: 2026-09-28 07:05:36 | AB3: 961564 | AC3: COA FLUVIAL-AM | AD3: GP | AE3: 2026-10-01 07:00:00 | AF3: 2026-10-01 07:31:35 | AG3: 32 | AH3: 2026-10-01 07:31:35 | AI3: 2026-10-02 07:11:10 | AJ3: 1422 | AK3: 2026-10-02 07:12:49 | AL3: 2026-10-02 10:34:23 | AM3: 202 | AN3: =IF(X3="",0,1) -> 1 | AO3: =IF(AI3="",0,1) -> 1 | AP3: =DATE(YEAR(AE3),MONTH(AE3),DAY(AE3)) -> 46296 | AQ3: =IF(COUNTIF('同场线路Rotas do mesmo SC'!A:A,C3)>0,"Sim","Não") -> Não | AR3: =IF(COUNTIF(揽收业务网点!A:A,P3)>0,"Sim","Não") -> Não
A4: SRTR22605673960 | B4: Concluído：已完成 | C4: JGS-F163-F136-F162-2200-1 | D4: Horário padrão | E4: Entrega | F4: 1 | G4: 180 | H4: JHX4C23 | I4: Truck | J4: RANYELLE SANTANA SILVA MARTINS | K4: Frota-自营 | L4: RVSSM | M4: ADRIANO ALEXANDRE DA SILVA | N4: 989851421 | O4: 781160 | P4: CPV 02-PB | Q4: CE | R4: 44 | S4: 41 | T4: 2026-09-30 05:27:16 | U4: 2026-09-30 05:40:51 | V4: 14 | W4: Não | X4: 2026-09-30 05:44:20 | Y4: 2026-10-01 03:30:00 | Z4: 2026-09-30 05:48:47 | AA4: 2026-09-30 05:48:47 | AB4: 883105 | AC4: PTS -PB | AD4: CE | AE4: 2026-10-01 07:30:00 | AF4: 2026-09-30 09:24:04 | AG4: -1325 | AH4: 2026-09-30 09:24:04 | AI4: 2026-09-30 09:32:04 | AJ4: 9 | AK4: 2026-09-30 09:32:18 | AL4: 2026-09-30 11:11:49 | AM4: 100 | AN4: =IF(X4="",0,1) -> 1 | AO4: =IF(AI4="",0,1) -> 1 | AP4: =DATE(YEAR(AE4),MONTH(AE4),DAY(AE4)) -> 46296 | AQ4: =IF(COUNTIF('同场线路Rotas do mesmo SC'!A:A,C4)>0,"Sim","Não") -> Não | AR4: =IF(COUNTIF(揽收业务网点!A:A,P4)>0,"Sim","Não") -> Não
A5: SRTR22605683400 | B5: Concluído：已完成 | C5: STM-C427-0500-1 | D5: Horário padrão | E5: Entrega | F5: 1 | G5: 264 | H5: OGT4E97 | I5: 3/4 | J5: SERGIO MANUEL LIMA DA SILVA | K5: Transportadora-三方 | L5: ATIVA T | M5: CARLOS ALBERTO DOS SANTOS NUNES JUNIOR | N5: 994640724 | O5: 89000 | P5: PA STM | Q5: GP | R5: 1398 | S5: 1014 | T5: 2026-09-28 20:36:18 | U5: 2026-09-28 20:45:26 | V5: 10 | W5: Não | X5: 2026-09-28 21:36:17 | Y5: 2026-09-29 05:00:00 | Z5: 2026-09-28 22:22:22 | AA5: 2026-09-28 22:22:22 | AB5: 961381 | AC5: F PRT -AM | AD5: GP | AE5: 2026-10-01 07:00:00 | AF5: 2026-10-01 06:29:51 | AG5: -30 | AH5: 2026-10-01 06:29:51 | AI5: 2026-10-01 06:31:40 | AJ5: 9 | AK5: 2026-10-01 06:38:11 | AL5: 2026-10-01 07:42:56 | AM5: 65 | AN5: =IF(X5="",0,1) -> 1 | AO5: =IF(AI5="",0,1) -> 1 | AP5: =DATE(YEAR(AE5),MONTH(AE5),DAY(AE5)) -> 46296 | AQ5: =IF(COUNTIF('同场线路Rotas do mesmo SC'!A:A,C5)>0,"Sim","Não") -> Não | AR5: =IF(COUNTIF(揽收业务网点!A:A,P5)>0,"Sim","Não") -> Não
A6: SRTR22605687811 | B6: Concluído：已完成 | C6: ANA-C537-0600-1 | D6: Horário padrão | E6: Entrega | F6: 1 | G6: 800 | H6: TWF0F29 | I6: Barco | J6: SAO DOMINGOS NAVEGACAO LTDA | K6: Transportadora-三方 | L6: SD | M6: VALDIR VIEIRA CORREA JUNIOR | N6: 91985099819 | O6: 89101 | P6: PA ANA | Q6: GP | R6: 2689 | S6: 1375 | T6: 2026-09-28 08:53:13 | U6: 2026-09-28 21:56:30 | V6: 784 | W6: Não | X6: 2026-09-29 02:41:13 | Y6: 2026-09-29 06:00:00 | Z6: 2026-09-29 03:48:41 | AA6: 2026-09-29 03:48:41 | AB6: 961491 | AC6: F BRV 02 -PA | AD6: GP | AE6: 2026-10-01 07:00:00 | AF6: 2026-09-30 09:51:46 | AG6: -1268 | AH6: 2026-09-30 09:51:46 | AI6: 2026-09-30 09:58:27 | AJ6: 9 | AK6: 2026-09-30 10:00:30 | AL6: 2026-09-30 11:13:04 | AM6: 73 | AN6: =IF(X6="",0,1) -> 1 | AO6: =IF(AI6="",0,1) -> 1 | AP6: =DATE(YEAR(AE6),MONTH(AE6),DAY(AE6)) -> 46296 | AQ6: =IF(COUNTIF('同场线路Rotas do mesmo SC'!A:A,C6)>0,"Sim","Não") -> Não | AR6: =IF(COUNTIF(揽收业务网点!A:A,P6)>0,"Sim","Não") -> Não
A7: SRTR22605691320 | B7: Concluído：已完成 | C7: ANA-C492-0600-1 | D7: Horário padrão | E7: Entrega | F7: 1 | G7: 800 | H7: 0937799 | I7: Barco | J7: NAVEGACAO OLIVEIRA LTDA | K7: Transportadora-三方 | L7: ANAMARQUES | M7: ALANA OLIVEIRA DO NASCIMENTO | N7: 96991413173 | O7: 89101 | P7: PA ANA | Q7: GP | R7: 332 | S7: 324 | T7: 2026-09-28 08:59:37 | U7: 2026-09-29 02:01:17 | V7: 1022 | W7: Não | X7: 2026-09-29 02:10:48 | Y7: 2026-09-29 06:00:00 | Z7: 2026-09-29 03:48:28 | AA7: 2026-09-29 03:48:28 | AB7: 961446 | AC7: LRJ-AP | AD7: GP | AE7: 2026-10-01 10:00:00 | AF7: 2026-09-30 22:07:16 | AG7: -712 | AH7: 2026-09-30 22:07:16 | AI7: 2026-10-02 14:35:44 | AJ7: 2433 | AK7: 2026-10-02 14:39:20 | AL7: 2026-10-03 08:08:26 | AM7: 1050 | AN7: =IF(X7="",0,1) -> 1 | AO7: =IF(AI7="",0,1) -> 1 | AP7: =DATE(YEAR(AE7),MONTH(AE7),DAY(AE7)) -> 46296 | AQ7: =IF(COUNTIF('同场线路Rotas do mesmo SC'!A:A,C7)>0,"Sim","Não") -> Não | AR7: =IF(COUNTIF(揽收业务网点!A:A,P7)>0,"Sim","Não") -> Não
A8: SRTR22605698631 | B8: Concluído：已完成 | C8: MAO1-C610-0700-1 | D8: Horário padrão | E8: Entrega | F8: 1 | G8: 500 | H8: JWP3563 | I8: 3/4 | J8: DARLISSON DANIEL MARQUES SOUSA | K8: Transportadora-三方 | L8: DARLISSON | M8: DARLISSON DANIEL MARQUES SOUSA | N8: 92985204417 | O8: 89202 | P8: DC MAO-AM | Q8: GP | R8: 399 | S8: 345 | T8: 2026-09-29 06:49:45 | U8: 2026-09-29 06:49:49 | V8: 1 | W8: Não | X8: 2026-09-29 06:54:11 | Y8: 2026-09-29 07:00:00 | Z8: 2026-09-29 06:54:39 | AA8: 2026-09-29 06:54:39 | AB8: 961564 | AC8: COA FLUVIAL-AM | AD8: GP | AE8: 2026-10-02 07:00:00 | AF8: 2026-10-01 07:30:26 | AG8: -1409 | AH8: 2026-10-01 07:30:26 | AI8: 2026-10-01 07:31:00 | AJ8: 4 | AK8: 2026-10-01 07:34:06 | AL8: 2026-10-01 09:52:24 | AM8: 139 | AN8: =IF(X8="",0,1) -> 1 | AO8: =IF(AI8="",0,1) -> 1 | AP8: =DATE(YEAR(AE8),MONTH(AE8),DAY(AE8)) -> 46297 | AQ8: =IF(COUNTIF('同场线路Rotas do mesmo SC'!A:A,C8)>0,"Sim","Não") -> Não | AR8: =IF(COUNTIF(揽收业务网点!A:A,P8)>0,"Sim","Não") -> Não
A9: SRTR22605702080 | B9: Concluído：已完成 | C9: THE-H206-H217-2200-1 | D9: Horário padrão | E9: Entrega | F9: 1 | G9: 375 | H9: QRZ0E84 | I9: Furgao | J9: AFA DE S OLIVEIRA TRANSPORTADO | K9: Transportadora-三方 | L9: ANDREIA | M9: WENDEL RIBEIRO | N9: 86998631695 | O9: 88601 | P9: PI THE | Q9: CE | R9: 2265 | S9: 1407 | T9: 2026-09-30 18:20:12 | U9: 2026-09-30 18:44:45 | V9: 25 | W9: Não | X9: 2026-09-30 20:30:38 | Y9: 2026-09-30 22:00:00 | Z9: 2026-09-30 20:54:53 | AA9: 2026-09-30 20:54:53 | AB9: 898114 | AC9: ITM -MA | AD9: CE | AE9: 2026-10-01 05:00:00 | AF9: 2026-10-01 03:29:21 | AG9: -90 | AH9: 2026-10-01 03:29:21 | AI9: 2026-10-01 03:32:54 | AJ9: 87 | AK9: 2026-10-01 04:56:06 | AL9: 2026-10-01 06:25:12 | AM9: 90 | AN9: =IF(X9="",0,1) -> 1 | AO9: =IF(AI9="",0,1) -> 1 | AP9: =DATE(YEAR(AE9),MONTH(AE9),DAY(AE9)) -> 46296 | AQ9: =IF(COUNTIF('同场线路Rotas do mesmo SC'!A:A,C9)>0,"Sim","Não") -> Não | AR9: =IF(COUNTIF(揽收业务网点!A:A,P9)>0,"Sim","Não") -> Não
A10: SRTR22605702091 | B10: Concluído：已完成 | C10: H104-H202-2000-1 | D10: Horário padrão | E10: Entrega | F10: 1 | G10: 391 | H10: RCJ5H28 | I10: Truck | J10: JOSIVAL FERREIRA DA SILVA | K10: Transportadora-三方 | L10: JOSIVAL FE | M10: EDINALDO OLIVEIRA DE LUCENA | N10: 99992241748 | O10: 899002 | P10: DC IMP-MA | Q10: CE | R10: 1564 | S10: 1333 | T10: 2026-09-30 15:19:39 | U10: 2026-09-30 15:27:20 | V10: 8 | W10: Não | X10: 2026-09-30 15:33:16 | Y10: 2026-09-30 20:00:00 | Z10: 2026-09-30 15:40:55 | AA10: 2026-09-30 15:40:55 | AB10: 899107 | AC10: BSS -MA | AD10: CE | AE10: 2026-10-01 04:00:00 | AF10: 2026-10-01 03:02:42 | AG10: -57 | AH10: 2026-10-01 03:02:42 | AI10: 2026-10-01 05:15:32 | AJ10: 143 | AK10: 2026-10-01 05:25:01 | AL10: 2026-10-01 08:39:46 | AM10: 195 | AN10: =IF(X10="",0,1) -> 1 | AO10: =IF(AI10="",0,1) -> 1 | AP10: =DATE(YEAR(AE10),MONTH(AE10),DAY(AE10)) -> 46296 | AQ10: =IF(COUNTIF('同场线路Rotas do mesmo SC'!A:A,C10)>0,"Sim","Não") -> Não | AR10: =IF(COUNTIF(揽收业务网点!A:A,P10)>0,"Sim","Não") -> Não
A11: SRTR22605702560 | B11: Concluído：已完成 | C11: RBR1-O03-O02-O04-1100-1 | D11: Horário padrão | E11: Entrega | F11: 1 | G11: 400 | H11: AWQ6F13 | I11: 3/4 | J11: FABIO FERREIRA DA SILVA | K11: Transportadora-三方 | L11: FABIO FER. | M11: TAC CARRO - FABIO FERREIRA DA SILVA | N11: 68999818172 | O11: 86802 | P11: DC RBR-AC | Q11: GP | R11: 6710 | S11: 3518 | T11: 2026-09-30 06:10:23 | U11: 2026-09-30 06:12:58 | V11: 3 | W11: Não | X11: 2026-09-30 06:15:34 | Y11: 2026-09-30 11:00:00 | Z11: 2026-09-30 06:15:19 | AA11: 2026-09-30 06:15:19 | AB11: 868101 | AC11: SMD -AC | AD11: GP | AE11: 2026-10-01 15:00:00 | AF11: 2026-10-01 01:00:00 | AG11: -840 | AH11: 2026-10-01 01:00:00 | AN11: =IF(X11="",0,1) -> 1 | AO11: =IF(AI11="",0,1) -> 0 | AP11: =DATE(YEAR(AE11),MONTH(AE11),DAY(AE11)) -> 46296 | AQ11: =IF(COUNTIF('同场线路Rotas do mesmo SC'!A:A,C11)>0,"Sim","Não") -> Não | AR11: =IF(COUNTIF(揽收业务网点!A:A,P11)>0,"Sim","Não") -> Não
A12: SRTR22605702680 | B12: Concluído：已完成 | C12: ANA-I269-0600-1 | D12: Horário padrão | E12: Entrega | F12: 1 | G12: 600 | H12: 0920411 | I12: Barco | J12: NV IRMAOS SANTANA /ANA BEATRIZ | K12: Transportadora-三方 | L12: AnaBEATRIZ | M12: ALANA OLIVEIRA DO NASCIMENTO | N12: 96991413173 | O12: 89101 | P12: PA ANA | Q12: GP | R12: 2906 | S12: 1267 | T12: 2026-09-29 09:24:08 | U12: 2026-09-30 02:34:55 | V12: 1031 | W12: Não | X12: 2026-09-30 04:16:31 | Y12: 2026-09-30 06:00:00 | Z12: 2026-09-30 04:28:11 | AA12: 2026-09-30 04:28:11 | AB12: 896104 | AC12: MCP FLUVIAL -AP | AD12: GP | AE12: 2026-10-01 23:59:00 | AF12: 2026-10-01 07:00:00 | AG12: -1019 | AH12: 2026-10-01 07:00:00 | AI12: 2026-10-01 20:36:04 | AJ12: 840 | AK12: 2026-10-01 20:59:26 | AL12: 2026-10-02 01:01:11 | AM12: 242 | AN12: =IF(X12="",0,1) -> 1 | AO12: =IF(AI12="",0,1) -> 1 | AP12: =DATE(YEAR(AE12),MONTH(AE12),DAY(AE12)) -> 46296 | AQ12: =IF(COUNTIF('同场线路Rotas do mesmo SC'!A:A,C12)>0,"Sim","Não") -> Não | AR12: =IF(COUNTIF(揽收业务网点!A:A,P12)>0,"Sim","Não") -> Não
A13: SRTR22605702851 | B13: Concluído：已完成 | C13: CGE-M119-1900-1 | D13: Horário padrão | E13: Entrega | F13: 1 | G13: 413 | H13: TZT7A69 | I13: Truck | J13: MGL TRASNPORTES E SERVIÇOS | K13: Transportadora-三方 | L13: MGL | M13: JOSE CARLOS SOUSA SILVA DE LIMA | N13: 38998845392 | O13: 53102 | P13: MG CGE | Q13: MG | R13: 11620 | S13: 11544 | T13: 2026-09-30 15:06:38 | U13: 2026-09-30 17:49:14 | V13: 163 | W13: Não | X13: 2026-09-30 18:00:03 | Y13: 2026-09-30 19:00:00 | Z13: 2026-09-30 18:01:28 | AA13: 2026-09-30 18:01:28 | AB13: 538001 | AC13: DC MTC-MG | AD13: MG | AE13: 2026-10-01 02:00:00 | AF13: 2026-10-01 00:42:48 | AG13: -77 | AH13: 2026-10-01 00:42:48 | AI13: 2026-10-01 00:49:49 | AJ13: 76 | AK13: 2026-10-01 01:58:37 | AL13: 2026-10-01 17:31:22 | AM13: 933 | AN13: =IF(X13="",0,1) -> 1 | AO13: =IF(AI13="",0,1) -> 1 | AP13: =DATE(YEAR(AE13),MONTH(AE13),DAY(AE13)) -> 46296 | AQ13: =IF(COUNTIF('同场线路Rotas do mesmo SC'!A:A,C13)>0,"Sim","Não") -> Não | AR13: =IF(COUNTIF(揽收业务网点!A:A,P13)>0,"Sim","Não") -> Não
A14: SRTR22605703260 | B14: Concluído：已完成 | C14: STM-I224-2300-1 | D14: Horário padrão | E14: Entrega | F14: 1 | G14: 225 | H14: TWS5B46 | I14: 3/4 | J14: ERICA RAIANA PINTO DA ROCHA | K14: Transportadora-三方 | L14: E. ROCHA | M14: LUIZ GUSTAVO PINTO PEREIRA | N14: 992147307 | O14: 89000 | P14: PA STM | Q14: GP | R14: 1070 | S14: 756 | T14: 2026-09-30 20:57:03 | U14: 2026-09-30 21:17:03 | V14: 21 | W14: Não | X14: 2026-09-30 22:29:33 | Y14: 2026-09-30 23:00:00 | Z14: 2026-09-30 22:35:10 | AA14: 2026-09-30 22:35:10 | AB14: 893107 | AC14: URA -PA | AD14: GP | AE14: 2026-10-01 06:00:00 | AF14: 2026-10-01 06:03:26 | AG14: 4 | AH14: 2026-10-01 06:03:26 | AI14: 2026-10-01 07:11:40 | AJ14: 65 | AK14: 2026-10-01 07:08:06 | AL14: 2026-10-01 08:57:43 | AM14: 110 | AN14: =IF(X14="",0,1) -> 1 | AO14: =IF(AI14="",0,1) -> 1 | AP14: =DATE(YEAR(AE14),MONTH(AE14),DAY(AE14)) -> 46296 | AQ14: =IF(COUNTIF('同场线路Rotas do mesmo SC'!A:A,C14)>0,"Sim","Não") -> Não | AR14: =IF(COUNTIF(揽收业务网点!A:A,P14)>0,"Sim","Não") -> Não
A15: SRTR22605703300 | B15: Concluído：已完成 | C15: S294-BRE-2330-1 | D15: Horário padrão | E15: Coleta | F15: 1 | G15: 104 | H15: ELQ5700 | I15: 3/4 | J15: CEOS EXPRESS | K15: Transportadora-三方 | L15: CEOS EXPRE | M15: JUAN JOSE GONZAGA SILVA | N15: 11954519066 | O15: 311200 | P15: PA PEGAKI-VCP-SP | Q15: SPS | R15: 1134 | S15: 1134 | T15: 2026-09-30 18:25:20 | U15: 2026-09-30 22:09:33 | V15: 225 | W15: Não | X15: 2026-09-30 22:16:21 | Y15: 2026-09-30 23:30:00 | Z15: 2026-09-30 19:23:16 | AA15: 2026-09-30 19:23:16 | AB15: 31101 | AC15: SP BRE | AD15: SPS | AE15: 2026-10-01 02:30:00 | AF15: 2026-10-01 00:27:33 | AG15: -122 | AH15: 2026-10-01 00:27:33 | AI15: 2026-10-01 00:36:17 | AJ15: 33 | AK15: 2026-10-01 00:59:36 | AL15: 2026-10-05 11:20:03 | AM15: 6381 | AN15: =IF(X15="",0,1) -> 1 | AO15: =IF(AI15="",0,1) -> 1 | AP15: =DATE(YEAR(AE15),MONTH(AE15),DAY(AE15)) -> 46296 | AQ15: =IF(COUNTIF('同场线路Rotas do mesmo SC'!A:A,C15)>0,"Sim","Não") -> Não | AR15: =IF(COUNTIF(揽收业务网点!A:A,P15)>0,"Sim","Não") -> Sim
A16: SRTR22605703640 | B16: Concluído：已完成 | C16: S343-RAO-2300-1 | D16: Horário padrão | E16: Coleta | F16: 1 | G16: 145 | H16: EFV8C09 | I16: Cavalo | J16: MULLER ENXOVAIS LTDA | K16: Transportadora-三方 | L16: MULLER ENX | M16: maycon lucas ferreira | N16: 16981876694 | O16: 316375 | P16: F IBG-SP | Q16: SPN | R16: 7808 | S16: 7808 | T16: 2026-09-30 14:14:21 | U16: 2026-09-30 17:14:00 | V16: 180 | W16: Não | X16: 2026-09-30 17:23:52 | Y16: 2026-09-30 23:00:00 | Z16: 2026-09-30 17:26:24 | AA16: 2026-09-30 17:26:24 | AB16: 31601 | AC16: SN RAO | AD16: SPN | AE16: 2026-10-01 01:40:00 | AF16: 2026-09-30 21:06:40 | AG16: -273 | AH16: 2026-09-30 21:06:40 | AI16: 2026-10-01 00:55:41 | AJ16: 231 | AK16: 2026-10-01 00:56:42 | AL16: 2026-10-01 05:59:36 | AM16: 303 | AN16: =IF(X16="",0,1) -> 1 | AO16: =IF(AI16="",0,1) -> 1 | AP16: =DATE(YEAR(AE16),MONTH(AE16),DAY(AE16)) -> 46296 | AQ16: =IF(COUNTIF('同场线路Rotas do mesmo SC'!A:A,C16)>0,"Sim","Não") -> Não | AR16: =IF(COUNTIF(揽收业务网点!A:A,P16)>0,"Sim","Não") -> Sim
A17: SRTR22605703760 | B17: Concluído：已完成 | C17: STM-I217-1900-1 | D17: Horário padrão | E17: Entrega | F17: 1 | G17: 370 | H17: QVL2J83 | I17: Truck | J17: S V DA ROCHA TRANSPORTES | K17: Transportadora-三方 | L17: EXPRES STM | M17: ERLISON RICARDO PINTO DA ROCHA | N17: 93991406800 | O17: 89000 | P17: PA STM | Q17: GP | R17: 1705 | S17: 1385 | T17: 2026-09-30 16:49:27 | U17: 2026-09-30 17:35:19 | V17: 46 | W17: Não | X17: 2026-09-30 17:53:31 | Y17: 2026-09-30 19:00:00 | Z17: 2026-09-30 17:56:19 | AA17: 2026-09-30 17:56:19 | AB17: 893104 | AC17: ITT -PA | AD17: GP | AE17: 2026-10-01 07:00:00 | AF17: 2026-10-01 05:53:13 | AG17: -66 | AH17: 2026-10-01 05:53:13 | AI17: 2026-10-01 08:50:23 | AJ17: 175 | AK17: 2026-10-01 08:47:44 | AL17: 2026-10-02 10:55:07 | AM17: 1568 | AN17: =IF(X17="",0,1) -> 1 | AO17: =IF(AI17="",0,1) -> 1 | AP17: =DATE(YEAR(AE17),MONTH(AE17),DAY(AE17)) -> 46296 | AQ17: =IF(COUNTIF('同场线路Rotas do mesmo SC'!A:A,C17)>0,"Sim","Não") -> Não | AR17: =IF(COUNTIF(揽收业务网点!A:A,P17)>0,"Sim","Não") -> Não
A18: SRTR22605703820 | B18: Concluído：已完成 | C18: JGS-F163-F136-F162-2200-1 | D18: Horário padrão | E18: Entrega | F18: 1 | G18: 214 | H18: NQA0D23 | I18: Toco | J18: RENNAM CABRAL DE OLIVEIRA | K18: Transportadora-三方 | L18: RENNAM TR | M18: RENNAM CABRAL DE OLIVEIRA | N18: 81985460015 | O18: 78101 | P18: PE JGS | Q18: CE | R18: 5872 | S18: 4858 | T18: 2026-09-30 14:04:00 | U18: 2026-09-30 21:45:38 | V18: 462 | W18: Não | X18: 2026-09-30 22:34:11 | Y18: 2026-09-30 22:00:00 | Z18: 2026-09-30 22:58:40 | AA18: 2026-09-30 22:58:40 | AB18: 883107 | AC18: CPV -PB | AD18: CE | AE18: 2026-10-01 03:30:00 | AF18: 2026-10-01 03:23:33 | AG18: -6 | AH18: 2026-10-01 03:23:33 | AI18: 2026-10-01 03:43:13 | AJ18: 171 | AK18: 2026-10-01 06:14:16 | AL18: 2026-10-02 06:27:21 | AM18: 1454 | AN18: =IF(X18="",0,1) -> 1 | AO18: =IF(AI18="",0,1) -> 1 | AP18: =DATE(YEAR(AE18),MONTH(AE18),DAY(AE18)) -> 46296 | AQ18: =IF(COUNTIF('同场线路Rotas do mesmo SC'!A:A,C18)>0,"Sim","Não") -> Não | AR18: =IF(COUNTIF(揽收业务网点!A:A,P18)>0,"Sim","Não") -> Não
A19: SRTR22605703820 | B19: Concluído：已完成 | C19: JGS-F163-F136-F162-2200-1 | D19: Horário padrão | E19: Entrega | F19: 1 | G19: 180 | H19: NQA0D23 | I19: Toco | J19: RENNAM CABRAL DE OLIVEIRA | K19: Transportadora-三方 | L19: RENNAM TR | M19: RENNAM CABRAL DE OLIVEIRA | N19: 81985460015 | O19: 781160 | P19: CPV 02-PB | Q19: CE | R19: 18 | S19: 18 | T19: 2026-10-01 05:38:54 | U19: 2026-10-01 05:38:54 | V19: 0 | W19: Não | X19: 2026-10-01 05:41:05 | Y19: 2026-10-02 04:00:00 | Z19: 2026-10-01 05:45:38 | AA19: 2026-10-01 05:45:38 | AB19: 883105 | AC19: PTS -PB | AD19: CE | AE19: 2026-10-02 08:00:00 | AF19: 2026-10-01 08:43:17 | AG19: -1396 | AH19: 2026-10-01 08:43:17 | AI19: 2026-10-01 08:51:13 | AJ19: 9 | AK19: 2026-10-01 08:52:06 | AL19: 2026-10-01 11:30:26 | AM19: 159 | AN19: =IF(X19="",0,1) -> 1 | AO19: =IF(AI19="",0,1) -> 1 | AP19: =DATE(YEAR(AE19),MONTH(AE19),DAY(AE19)) -> 46297 | AQ19: =IF(COUNTIF('同场线路Rotas do mesmo SC'!A:A,C19)>0,"Sim","Não") -> Não | AR19: =IF(COUNTIF(揽收业务网点!A:A,P19)>0,"Sim","Não") -> Não
A20: SRTR22605704071 | B20: Concluído：已完成 | C20: S236-BRE-2200-2 | D20: Horário padrão | E20: Coleta | F20: 2 | G20: 24 | H20: FSR4520 | I20: Truck | J20: DEBORA TRANSPORTES | K20: Transportadora-三方 | L20: DEB | M20: SILVIO DE ANDRADE | N20: 11971583378 | O20: 311111 | P20: PA MANDAE-SP | Q20: SPS | R20: 1848 | S20: 1848 | T20: 2026-09-30 20:01:13 | U20: 2026-09-30 21:35:18 | V20: 95 | W20: Não | X20: 2026-09-30 21:37:36 | Y20: 2026-09-30 22:00:00 | Z20: 2026-09-30 21:42:53 | AA20: 2026-09-30 21:42:53 | AB20: 31101 | AC20: SP BRE | AD20: SPS | AE20: 2026-10-01 00:00:00 | AF20: 2026-09-30 23:04:31 | AG20: -55 | AH20: 2026-09-30 23:04:31 | AI20: 2026-09-30 22:53:10 | AJ20: 3 | AK20: 2026-09-30 23:06:38 | AL20: 2026-10-03 05:43:50 | AM20: 3278 | AN20: =IF(X20="",0,1) -> 1 | AO20: =IF(AI20="",0,1) -> 1 | AP20: =DATE(YEAR(AE20),MONTH(AE20),DAY(AE20)) -> 46296 | AQ20: =IF(COUNTIF('同场线路Rotas do mesmo SC'!A:A,C20)>0,"Sim","Não") -> Não | AR20: =IF(COUNTIF(揽收业务网点!A:A,P20)>0,"Sim","Não") -> Sim
A21: SRTR22605704451 | B21: Concluído：已完成 | C21: FEC-E305-0200-1 | D21: Horário padrão | E21: Entrega | F21: 1 | G21: 103 | H21: NZQ6E08 | I21: Furgao | J21: RODO BELLA TRANSPORTE LTDA | K21: Transportadora-三方 | L21: RODOBELLA | M21: LEANDRO SANTANA DOS SANTOS | N21: 988678172 | O21: 77501 | P21: BA FEC | Q21: BA | R21: 1247 | S21: 1090 | T21: 2026-09-29 16:38:59 | U21: 2026-09-30 00:07:29 | V21: 449 | W21: Não | X21: 2026-09-30 00:13:04 | Y21: 2026-09-30 02:00:00 | Z21: 2026-09-30 00:20:04 | AA21: 2026-09-30 00:20:04 | AB21: 773124 | AC21: POLI-BA | AD21: BA | AE21: 2026-10-01 08:10:00 | AF21: 2026-09-30 05:17:29 | AG21: -1612 | AH21: 2026-09-30 05:17:29 | AI21: 2026-09-30 05:50:33 | AJ21: 41 | AK21: 2026-09-30 05:58:03 | AL21: 2026-09-30 07:20:34 | AM21: 83 | AN21: =IF(X21="",0,1) -> 1 | AO21: =IF(AI21="",0,1) -> 1 | AP21: =DATE(YEAR(AE21),MONTH(AE21),DAY(AE21)) -> 46296 | AQ21: =IF(COUNTIF('同场线路Rotas do mesmo SC'!A:A,C21)>0,"Sim","Não") -> Não | AR21: =IF(COUNTIF(揽收业务网点!A:A,P21)>0,"Sim","Não") -> Não
A22: SRTR22605704951 | B22: Concluído：已完成 | C22: STM-I272-2300-1 | D22: Horário padrão | E22: Entrega | F22: 1 | G22: 10 | H22: RXE7I39 | I22: 3/4 | J22: JET EXPRESS PA | K22: Frota-自营 | L22: JET PA | M22: EDIVALDO PIRES DE SOUZA | N22: 93992429221 | O22: 89000 | P22: PA STM | Q22: GP | R22: 495 | S22: 283 | T22: 2026-09-30 17:15:20 | U22: 2026-09-30 17:15:27 | V22: 1 | W22: Não | X22: 2026-09-30 17:20:02 | Y22: 2026-09-30 23:00:00 | Z22: 2026-09-30 17:22:25 | AA22: 2026-09-30 17:22:25 | AB22: 896105 | AC22: STM FLUVIAL -PA | AD22: GP | AE22: 2026-10-01 04:00:00 | AF22: 2026-09-30 17:22:34 | AG22: -637 | AH22: 2026-09-30 17:22:34 | AI22: 2026-09-30 17:23:40 | AJ22: 8 | AK22: 2026-09-30 17:29:45 | AL22: 2026-10-01 07:44:45 | AM22: 855 | AN22: =IF(X22="",0,1) -> 1 | AO22: =IF(AI22="",0,1) -> 1 | AP22: =DATE(YEAR(AE22),MONTH(AE22),DAY(AE22)) -> 46296 | AQ22: =IF(COUNTIF('同场线路Rotas do mesmo SC'!A:A,C22)>0,"Sim","Não") -> Não | AR22: =IF(COUNTIF(揽收业务网点!A:A,P22)>0,"Sim","Não") -> Não
A23: SRTR22605705220 | B23: Concluído：已完成 | C23: M209-BRE-2300-2 | D23: Horário padrão | E23: Coleta | F23: 2 | G23: 1 | H23: FCX7J05 | I23: Truck | J23: RHS TRANSPORTES E SERVIÇOS | K23: Transportadora-三方 | L23: RHS TRANS | M23: VALDECI ALVES DE OLIVEIRA JUNIOR | N23: 11932427923 | O23: 535104 | P23: EXT -MG | Q23: MG | R23: 7155 | S23: 6482 | T23: 2026-09-30 17:05:54 | U23: 2026-09-30 17:59:38 | V23: 54 | W23: Não | X23: 2026-09-30 18:04:04 | Y23: 2026-09-30 23:00:00 | Z23: 2026-09-30 17:01:24 | AA23: 2026-09-30 17:01:24 | AB23: 31101 | AC23: SP BRE | AD23: SPS | AE23: 2026-10-01 04:00:00 | AF23: 2026-09-30 21:06:02 | AG23: -413 | AH23: 2026-09-30 21:06:02 | AI23: 2026-09-30 23:07:45 | AJ23: 123 | AK23: 2026-09-30 23:08:33 | AL23: 2026-10-05 08:57:36 | AM23: 6350 | AN23: =IF(X23="",0,1) -> 1 | AO23: =IF(AI23="",0,1) -> 1 | AP23: =DATE(YEAR(AE23),MONTH(AE23),DAY(AE23)) -> 46296 | AQ23: =IF(COUNTIF('同场线路Rotas do mesmo SC'!A:A,C23)>0,"Sim","Não") -> Não | AR23: =IF(COUNTIF(揽收业务网点!A:A,P23)>0,"Sim","Não") -> Sim
... A26: SRTR22605706200 | B26: Concluído：已完成 | C26: M209-BRE-2203-4 | D26: Horário padrão | E26: Coleta | F26: 4 | G26: 132 | H26: DVT3F87 | I26: Truck | J26: WILIAN CARLOS DE OLIVEIRA | K26: Transportadora-三方 | L26: WILIAN | M26: diovani iran francisco da silva | N26: 3597327569 | O26: 535104 | P26: EXT -MG | Q26: MG | R26: 7022 | S26: 7021 | T26: 2026-09-30 19:10:40 | U26: 2026-09-30 22:00:02 | V26: 170 | W26: Não | X26: 2026-09-30 21:41:08 | Y26: 2026-09-30 22:03:00 | Z26: 2026-09-30 20:57:51 | AA26: 2026-09-30 20:57:51 | AB26: 31101 | AC26: SP BRE | AD26: SPS | AE26: 2026-10-01 00:33:00 | AF26: 2026-10-01 00:31:42 | AG26: -1 | AH26: 2026-10-01 00:31:42 | AI26: 2026-10-01 01:28:14 | AJ26: -86 | AK26: 2026-09-30 23:04:55 | AL26: 2026-10-03 04:32:15 | AM26: 3208 | AN26: =IF(X26="",0,1) -> 1 | AO26: =IF(AI26="",0,1) -> 1 | AP26: =DATE(YEAR(AE26),MONTH(AE26),DAY(AE26)) -> 46296 | AQ26: =IF(COUNTIF('同场线路Rotas do mesmo SC'!A:A,C26)>0,"Sim","Não") -> Não | AR26: =IF(COUNTIF(揽收业务网点!A:A,P26)>0,"Sim","Não") -> Sim
A27: SRTR22605706280 | B27: Concluído：已完成 | C27: P110-P235-1400-2 | D27: Horário padrão | E27: Entrega | F27: 2 | G27: 640 | H27: AWP1D85 | I27: VUC | J27: ESTEFANI RODRIGUES DE JESUS M | K27: Transportadora-三方 | L27: ESTEFANI R | M27: KLEBER LOPES DE LIMA | N27: 4499213179 | O27: 244002 | P27: DC MGF-PR | Q27: PR | R27: 693 | S27: 670 | T27: 2026-09-30 02:49:18 | U27: 2026-09-30 06:18:45 | V27: 210 | W27: Não | Y27: 2026-09-30 14:00:00 | Z27: 2026-09-30 06:18:45 | AA27: 2026-09-30 06:18:45 | AB27: 244003 | AC27: MGF-PR | AD27: PR | AE27: 2026-10-01 00:40:00 | AF27: 2026-09-30 05:16:34 | AG27: -1163 | AH27: 2026-09-30 05:16:34 | AJ27: 10 | AK27: 2026-09-30 05:26:34 | AL27: 2026-09-30 07:00:21 | AM27: 94 | AN27: =IF(X27="",0,1) -> 0 | AO27: =IF(AI27="",0,1) -> 0 | AP27: =DATE(YEAR(AE27),MONTH(AE27),DAY(AE27)) -> 46296 | AQ27: =IF(COUNTIF('同场线路Rotas do mesmo SC'!A:A,C27)>0,"Sim","Não") -> Não | AR27: =IF(COUNTIF(揽收业务网点!A:A,P27)>0,"Sim","Não") -> Não
A28: SRTR22605707011 | B28: Concluído：已完成 | C28: P244-SJS-2330-2 | D28: Horário padrão | E28: Coleta | F28: 2 | G28: 30 | H28: QIG5E10 | I28: 3/4 | J28: 29.370.448 ADMILSON JOSE DE | K28: Transportadora-三方 | L28: ADMILSON | M28: ADMILSON JOSE DE MORAIS | N28: 41984557890 | O28: 241117 | P28: SJS -PR | Q28: PR | R28: 14262 | S28: 14262 | T28: 2026-09-29 09:58:04 | U28: 2026-09-30 22:00:10 | V28: 2163 | W28: Sim | X28: 2026-09-30 04:54:10 | Y28: 2026-09-30 23:30:00 | Z28: 2026-09-30 04:21:59 | AA28: 2026-09-30 04:21:59 | AB28: 24101 | AC28: PR SJS | AD28: PR | AE28: 2026-10-01 01:00:00 | AF28: 2026-09-30 11:22:18 | AG28: -817 | AH28: 2026-09-30 11:22:18 | AJ28: -740 | AK28: 2026-09-29 23:01:49 | AL28: 2026-10-02 12:57:35 | AM28: 3716 | AN28: =IF(X28="",0,1) -> 1 | AO28: =IF(AI28="",0,1) -> 0 | AP28: =DATE(YEAR(AE28),MONTH(AE28),DAY(AE28)) -> 46296 | AQ28: =IF(COUNTIF('同场线路Rotas do mesmo SC'!A:A,C28)>0,"Sim","Não") -> Não | AR28: =IF(COUNTIF(揽收业务网点!A:A,P28)>0,"Sim","Não") -> Sim
A29: SRTR22605707220 | B29: Concluído：已完成 | C29: FEC-E213-0200-1 | D29: Horário padrão | E29: Entrega | F29: 1 | G29: 115 | H29: JRJ2B79 | I29: Furgao | J29: RODO BELLA TRANSPORTE LTDA | K29: Transportadora-三方 | L29: RODOBELLA | M29: MAURICIO DE FIGUEIREDO SILVA | N29: 991735004 | O29: 77501 | P29: BA FEC | Q29: BA | R29: 896 | S29: 773 | T29: 2026-09-29 16:41:11 | U29: 2026-09-29 21:56:17 | V29: 316 | W29: Não | X29: 2026-09-29 23:56:36 | Y29: 2026-09-30 02:00:00 | Z29: 2026-09-30 00:12:23 | AA29: 2026-09-30 00:12:23 | AB29: 771106 | AC29: SSA -BA | AD29: BA | AE29: 2026-10-01 06:50:00 | AF29: 2026-09-30 03:10:38 | AG29: -1659 | AH29: 2026-09-30 03:10:38 | AI29: 2026-09-30 06:02:17 | AJ29: 213 | AK29: 2026-09-30 06:43:30 | AL29: 2026-10-01 08:33:24 | AM29: 1550 | AN29: =IF(X29="",0,1) -> 1 | AO29: =IF(AI29="",0,1) -> 1 | AP29: =DATE(YEAR(AE29),MONTH(AE29),DAY(AE29)) -> 46296 | AQ29: =IF(COUNTIF('同场线路Rotas do mesmo SC'!A:A,C29)>0,"Sim","Não") -> Não | AR29: =IF(COUNTIF(揽收业务网点!A:A,P29)>0,"Sim","Não") -> Não
A30: SRTR22605707300 | B30: Concluído：已完成 | C30: A002-A212-A272-A221-A372-2310-1 | D30: Horário padrão | E30: Entrega | F30: 1 | G30: 240 | H30: IWG3B32 | I30: 3/4 | J30: GUILHERME HENRIQUE DE LIMA | K30: Transportadora-三方 | L30: GUILHERME | M30: GUILHERME HENRIQUE DE LIMA ROSA | N30: 51992695994 | O30: 154001 | P30: DC PFB-RS | Q30: PR | R30: 2321 | S30: 2307 | T30: 2026-09-30 00:01:31 | U30: 2026-09-30 00:05:47 | V30: 5 | W30: Não | X30: 2026-09-30 00:07:35 | Y30: 2026-09-30 23:10:00 | Z30: 2026-09-30 00:24:19 | AA30: 2026-09-30 00:24:19 | AB30: 155102 | AC30: IJU -RS | AD30: PR | AE30: 2026-10-01 03:10:00 | AF30: 2026-09-30 03:02:03 | AG30: -1447 | AH30: 2026-09-30 03:02:03 | AN30: =IF(X30="",0,1) -> 1 | AO30: =IF(AI30="",0,1) -> 0 | AP30: =DATE(YEAR(AE30),MONTH(AE30),DAY(AE30)) -> 46296 | AQ30: =IF(COUNTIF('同场线路Rotas do mesmo SC'!A:A,C30)>0,"Sim","Não") -> Não | AR30: =IF(COUNTIF(揽收业务网点!A:A,P30)>0,"Sim","Não") -> Não
A31: SRTR22605707300 | B31: Concluído：已完成 | C31: A002-A212-A272-A221-A372-2310-1 | D31: Horário padrão | E31: Entrega | F31: 1 | G31: 90 | H31: IWG3B32 | I31: 3/4 | J31: GUILHERME HENRIQUE DE LIMA | K31: Transportadora-三方 | L31: GUILHERME | M31: GUILHERME HENRIQUE DE LIMA ROSA | N31: 51992695994 | O31: 155119 | P31: F IJI-RS | Q31: PR | R31: 7 | S31: 7 | T31: 2026-09-29 17:47:08 | U31: 2026-09-29 17:47:31 | V31: 1 | W31: Não | X31: 2026-09-30 03:38:26 | Y31: 2026-10-01 04:30:00 | Z31: 2026-09-30 03:39:53 | AA31: 2026-09-30 03:39:53 | AB31: 155105 | AC31: STR -RS | AD31: PR | AE31: 2026-10-01 06:00:00 | AF31: 2026-09-30 05:04:22 | AG31: -1495 | AH31: 2026-09-30 05:04:22 | AI31: 2026-09-30 05:43:27 | AJ31: 133 | AK31: 2026-09-30 07:16:24 | AL31: 2026-09-30 08:09:44 | AM31: 54 | AN31: =IF(X31="",0,1) -> 1 | AO31: =IF(AI31="",0,1) -> 1 | AP31: =DATE(YEAR(AE31),MONTH(AE31),DAY(AE31)) -> 46296 | AQ31: =IF(COUNTIF('同场线路Rotas do mesmo SC'!A:A,C31)>0,"Sim","Não") -> Não | AR31: =IF(COUNTIF(揽收业务网点!A:A,P31)>0,"Sim","Não") -> Não
A32: SRTR22605707511 | B32: Concluído：已完成 | C32: THE-H203-1800-1 | D32: Horário padrão | E32: Entrega | F32: 1 | G32: 370 | H32: FUX5A91 | I32: Truck | J32: JET EXPRESS CE | K32: Frota-自营 | L32: JET CE | M32: SAVIO SILVA DE SOUSA | N32: 86981545029 | O32: 88601 | P32: PI THE | Q32: CE | R32: 7307 | S32: 4947 | T32: 2026-09-30 16:55:42 | U32: 2026-09-30 17:43:20 | V32: 48 | W32: Não | X32: 2026-09-30 17:48:10 | Y32: 2026-09-30 18:00:00 | Z32: 2026-09-30 17:54:12 | AA32: 2026-09-30 17:54:12 | AB32: 898111 | AC32: STN -MA | AD32: CE | AE32: 2026-10-01 01:15:00 | AF32: 2026-10-01 00:40:28 | AG32: -34 | AH32: 2026-10-01 00:40:28 | AI32: 2026-10-01 01:08:16 | AJ32: 43 | AK32: 2026-10-01 01:23:20 | AL32: 2026-10-02 10:29:01 | AM32: 1986 | AN32: =IF(X32="",0,1) -> 1 | AO32: =IF(AI32="",0,1) -> 1 | AP32: =DATE(YEAR(AE32),MONTH(AE32),DAY(AE32)) -> 46296 | AQ32: =IF(COUNTIF('同场线路Rotas do mesmo SC'!A:A,C32)>0,"Sim","Não") -> Não | AR32: =IF(COUNTIF(揽收业务网点!A:A,P32)>0,"Sim","Não") -> Não
A33: SRTR22605707660 | B33: Concluído：已完成 | C33: STM-C410-0500-1 | D33: Horário padrão | E33: Entrega | F33: 1 | G33: 205 | H33: OGT4E97 | I33: 3/4 | J33: SERGIO MANUEL LIMA DA SILVA | K33: Transportadora-三方 | L33: ATIVA T | M33: JAIMISON LIMA PEREIRA | N33: 999769763 | O33: 89000 | P33: PA STM | Q33: GP | R33: 448 | S33: 283 | T33: 2026-09-29 21:52:43 | U33: 2026-09-29 21:53:46 | V33: 2 | W33: Não | X33: 2026-09-29 22:02:13 | Y33: 2026-09-30 05:00:00 | Z33: 2026-09-29 22:31:14 | AA33: 2026-09-29 22:31:14 | AB33: 961364 | AC33: F JRT-PA | AD33: GP | AE33: 2026-10-01 08:00:00 | AF33: 2026-10-01 08:52:24 | AG33: 53 | AH33: 2026-10-01 08:52:24 | AI33: 2026-10-01 08:54:04 | AJ33: 8 | AK33: 2026-10-01 08:59:33 | AL33: 2026-10-01 11:25:06 | AM33: 146 | AN33: =IF(X33="",0,1) -> 1 | AO33: =IF(AI33="",0,1) -> 1 | AP33: =DATE(YEAR(AE33),MONTH(AE33),DAY(AE33)) -> 46296 | AQ33: =IF(COUNTIF('同场线路Rotas do mesmo SC'!A:A,C33)>0,"Sim","Não") -> Não | AR33: =IF(COUNTIF(揽收业务网点!A:A,P33)>0,"Sim","Não") -> Não
A34: SRTR22605707871 | B34: Concluído：已完成 | C34: JGS-F56-2300-1 | D34: Horário padrão | E34: Entrega | F34: 1 | G34: 129 | H34: FNS7D41 | I34: Truck | J34: MARCOS AURELIO PEREIRA DE SA | K34: Transportadora-三方 | L34: MARCOSAURE | M34: EDMAR MARTINS DA SILVA | N34: 989728618 | O34: 78101 | P34: PE JGS | Q34: CE | R34: 7860 | S34: 6182 | T34: 2026-09-30 14:43:05 | U34: 2026-09-30 22:42:39 | V34: 480 | W34: Não | X34: 2026-09-30 23:42:04 | Y34: 2026-09-30 23:00:00 | Z34: 2026-09-30 22:50:52 | AA34: 2026-09-30 22:50:52 | AB34: 883002 | AC34: DC BYE-PB | AD34: CE | AE34: 2026-10-01 02:00:00 | AF34: 2026-10-01 01:56:06 | AG34: -3 | AH34: 2026-10-01 01:56:06 | AI34: 2026-10-01 03:10:16 | AJ34: 52 | AK34: 2026-10-01 02:47:51 | AL34: 2026-10-01 03:15:02 | AM34: 28 | AN34: =IF(X34="",0,1) -> 1 | AO34: =IF(AI34="",0,1) -> 1 | AP34: =DATE(YEAR(AE34),MONTH(AE34),DAY(AE34)) -> 46296 | AQ34: =IF(COUNTIF('同场线路Rotas do mesmo SC'!A:A,C34)>0,"Sim","Não") -> Não | AR34: =IF(COUNTIF(揽收业务网点!A:A,P34)>0,"Sim","Não") -> Não
A35: SRTR22605707911 | B35: Concluído：已完成 | C35: RAO-D138-2300-1 | D35: Horário padrão | E35: Entrega | F35: 1 | G35: 205 | H35: LSE4I06 | I35: 3/4 | J35: LALALOG EXPRESS LTDA | K35: Transportadora-三方 | L35: LALALOG | M35: ANTONY JOABE DE OLIVEIRA VIANA | N35: 16982292807 | O35: 31601 | P35: SN RAO | Q35: SPN | R35: 1916 | S35: 1916 | T35: 2026-09-30 19:14:23 | U35: 2026-09-30 22:52:41 | V35: 219 | W35: Não | X35: 2026-09-30 22:53:35 | Y35: 2026-09-30 23:00:00 | Z35: 2026-09-30 22:28:35 | AA35: 2026-09-30 22:28:35 | AB35: 319153 | AC35: DC SJP-SP | AD35: SPN | AE35: 2026-10-01 01:50:00 | AF35: 2026-10-01 01:42:28 | AG35: -7 | AH35: 2026-10-01 01:42:28 | AI35: 2026-10-01 01:45:36 | AJ35: 12 | AK35: 2026-10-01 01:53:41 | AL35: 2026-10-01 03:22:47 | AM35: 90 | AN35: =IF(X35="",0,1) -> 1 | AO35: =IF(AI35="",0,1) -> 1 | AP35: =DATE(YEAR(AE35),MONTH(AE35),DAY(AE35)) -> 46296 | AQ35: =IF(COUNTIF('同场线路Rotas do mesmo SC'!A:A,C35)>0,"Sim","Não") -> Não | AR35: =IF(COUNTIF(揽收业务网点!A:A,P35)>0,"Sim","Não") -> Não
A36: SRTR22605707980 | B36: Concluído：已完成 | C36: M209-BRE-2202-6 | D36: Horário padrão | E36: Coleta | F36: 6 | G36: 132 | H36: RMZ8J06 | I36: Truck | J36: RHS TRANSPORTES E SERVIÇOS | K36: Transportadora-三方 | L36: RHS | M36: RODRIGO APARECIDO PASSOLONGO | N36: 11985286393 | O36: 535104 | P36: EXT -MG | Q36: MG | R36: 5145 | S36: 5145 | T36: 2026-09-30 07:21:39 | U36: 2026-09-30 20:36:24 | V36: 795 | W36: Não | X36: 2026-09-30 20:42:38 | Y36: 2026-09-30 22:02:00 | Z36: 2026-09-30 17:47:45 | AA36: 2026-09-30 17:47:45 | AB36: 31101 | AC36: SP BRE | AD36: SPS | AE36: 2026-10-01 00:32:00 | AF36: 2026-09-30 23:16:51 | AG36: -75 | AH36: 2026-09-30 23:16:51 | AI36: 2026-10-01 06:54:06 | AJ36: 264 | AK36: 2026-10-01 03:40:17 | AL36: 2026-10-03 06:51:57 | AM36: 3072 | AN36: =IF(X36="",0,1) -> 1 | AO36: =IF(AI36="",0,1) -> 1 | AP36: =DATE(YEAR(AE36),MONTH(AE36),DAY(AE36)) -> 46296 | AQ36: =IF(COUNTIF('同场线路Rotas do mesmo SC'!A:A,C36)>0,"Sim","Não") -> Não | AR36: =IF(COUNTIF(揽收业务网点!A:A,P36)>0,"Sim","Não") -> Sim
A37: SRTR22605708320 | B37: Concluído：已完成 | C37: STM-C380-1900-1 | D37: Horário padrão | E37: Entrega | F37: 1 | G37: 370 | H37: QVL2J83 | I37: Truck | J37: S V DA ROCHA TRANSPORTES | K37: Transportadora-三方 | L37: EXPRES STM | M37: ERLISON RICARDO PINTO DA ROCHA | N37: 93991406800 | O37: 89000 | P37: PA STM | Q37: GP | R37: 932 | S37: 774 | T37: 2026-09-30 16:42:40 | U37: 2026-09-30 17:08:46 | V37: 27 | W37: Não | X37: 2026-09-30 17:52:40 | Y37: 2026-09-30 19:00:00 | Z37: 2026-09-30 17:56:44 | AA37: 2026-09-30 17:56:44 | AB37: 961334 | AC37: F ITT-PA | AD37: GP | AE37: 2026-10-01 07:00:00 | AF37: 2026-10-01 07:10:07 | AG37: 11 | AH37: 2026-10-01 07:10:07 | AI37: 2026-10-01 07:37:10 | AJ37: 42 | AK37: 2026-10-01 07:51:58 | AL37: 2026-10-01 13:24:23 | AM37: 333 | AN37: =IF(X37="",0,1) -> 1 | AO37: =IF(AI37="",0,1) -> 1 | AP37: =DATE(YEAR(AE37),MONTH(AE37),DAY(AE37)) -> 46296 | AQ37: =IF(COUNTIF('同场线路Rotas do mesmo SC'!A:A,C37)>0,"Sim","Não") -> Não | AR37: =IF(COUNTIF(揽收业务网点!A:A,P37)>0,"Sim","Não") -> Não
A38: SRTR22605708511 | B38: Concluído：已完成 | C38: A285-BLU-2200-1 | D38: Horário padrão | E38: Coleta | F38: 1 | G38: 150 | H38: MME5F49 | I38: 3/4 | J38: TRANSPORTES CARVALHO LTDA | K38: Transportadora-三方 | L38: CARVALHO | M38: EDMAR OLIVEIRA FERREIRA | N38: 48996411466 | O38: 155133 | P38: SJE-SC | Q38: PR | R38: 2348 | S38: 2348 | T38: 2026-09-30 14:33:55 | U38: 2026-09-30 18:29:42 | V38: 236 | W38: Não | X38: 2026-09-30 18:42:57 | Y38: 2026-09-30 22:00:00 | Z38: 2026-09-30 18:46:14 | AA38: 2026-09-30 18:46:14 | AB38: 14804 | AC38: SC BLU | AD38: PR | AE38: 2026-10-01 00:30:00 | AF38: 2026-09-30 21:12:11 | AG38: -197 | AH38: 2026-09-30 21:12:11 | AI38: 2026-09-30 22:37:13 | AN38: =IF(X38="",0,1) -> 1 | AO38: =IF(AI38="",0,1) -> 1 | AP38: =DATE(YEAR(AE38),MONTH(AE38),DAY(AE38)) -> 46296 | AQ38: =IF(COUNTIF('同场线路Rotas do mesmo SC'!A:A,C38)>0,"Sim","Não") -> Não | AR38: =IF(COUNTIF(揽收业务网点!A:A,P38)>0,"Sim","Não") -> Sim
A39: SRTR22605708560 | B39: Concluído：已完成 | C39: M209-BRE-2200-5 | D39: Horário padrão | E39: Coleta | F39: 5 | G39: 150 | H39: IPA7I02 | I39: Truck | J39: WILIAN CARLOS DE OLIVEIRA | K39: Transportadora-三方 | L39: WILIAN | M39: EDERSON CARLOS DE OLIVEIRA | N39: 11958040524 | O39: 535104 | P39: EXT -MG | Q39: MG | R39: 9136 | S39: 9111 | T39: 2026-09-30 17:35:36 | U39: 2026-09-30 19:23:35 | V39: 108 | W39: Não | X39: 2026-09-30 19:30:49 | Y39: 2026-09-30 22:00:00 | Z39: 2026-09-30 18:09:55 | AA39: 2026-09-30 18:09:55 | AB39: 31101 | AC39: SP BRE | AD39: SPS | AE39: 2026-10-01 03:20:00 | AF39: 2026-09-30 22:15:52 | AG39: -304 | AH39: 2026-09-30 22:15:52 | AI39: 2026-09-30 22:27:41 | AJ39: 32 | AK39: 2026-09-30 22:47:20 | AL39: 2026-10-05 09:12:04 | AM39: 6385 | AN39: =IF(X39="",0,1) -> 1 | AO39: =IF(AI39="",0,1) -> 1 | AP39: =DATE(YEAR(AE39),MONTH(AE39),DAY(AE39)) -> 46296 | AQ39: =IF(COUNTIF('同场线路Rotas do mesmo SC'!A:A,C39)>0,"Sim","Não") -> Não | AR39: =IF(COUNTIF(揽收业务网点!A:A,P39)>0,"Sim","Não") -> Sim
A40: SRTR22605708880 | B40: Concluído：已完成 | C40: R350-SJM-1830-1 | D40: Horário padrão | E40: Coleta | F40: 1 | G40: 156 | H40: AUE8A13 | I40: Toco | J40: JMJ TRANSPORTE | K40: Transportadora-三方 | L40: JMJ TRANSP | M40: ALEX LIMA PEREIRA | N40: 21989931855 | O40: 691155 | P40: PA NVF-RJ | Q40: RJ | R40: 12646 | S40: 12646 | T40: 2026-09-30 17:07:11 | U40: 2026-09-30 17:58:08 | V40: 51 | W40: Não | X40: 2026-09-30 18:01:40 | Y40: 2026-09-30 18:30:00 | Z40: 2026-09-30 18:02:45 | AA40: 2026-09-30 18:02:45 | AB40: 62101 | AC40: RJ SJM | AD40: RJ | AE40: 2026-10-01 00:20:00 | AF40: 2026-09-30 21:05:38 | AG40: -194 | AH40: 2026-09-30 21:05:38 | AI40: 2026-09-30 22:24:51 | AJ40: 87 | AK40: 2026-09-30 22:31:56 | AL40: 2026-10-02 20:43:26 | AM40: 2772 | AN40: =IF(X40="",0,1) -> 1 | AO40: =IF(AI40="",0,1) -> 1 | AP40: =DATE(YEAR(AE40),MONTH(AE40),DAY(AE40)) -> 46296 | AQ40: =IF(COUNTIF('同场线路Rotas do mesmo SC'!A:A,C40)>0,"Sim","Não") -> Não | AR40: =IF(COUNTIF(揽收业务网点!A:A,P40)>0,"Sim","Não") -> Sim
A41: SRTR22605709840 | B41: Concluído：已完成 | C41: R350-SJM-2000-2 | D41: Horário padrão | E41: Coleta | F41: 2 | G41: 150 | H41: TME6G23 | I41: Truck | J41: JBSL TRANSPORTES LTDA | K41: Transportadora-三方 | L41: JBSL | M41: CARLOS EDUARDO DOS SANTOS FERREIRA | N41: 21965008441 | O41: 691155 | P41: PA NVF-RJ | Q41: RJ | R41: 21419 | S41: 21419 | T41: 2026-09-30 19:20:41 | U41: 2026-09-30 20:31:11 | V41: 71 | W41: Não | X41: 2026-09-30 20:31:47 | Y41: 2026-09-30 20:00:00 | Z41: 2026-09-29 21:27:04 | AA41: 2026-09-29 21:27:04 | AB41: 62101 | AC41: RJ SJM | AD41: RJ | AE41: 2026-10-01 02:40:00 | AF41: 2026-09-30 22:57:10 | AG41: -222 | AH41: 2026-09-30 22:57:10 | AI41: 2026-10-01 00:54:16 | AJ41: 97 | AK41: 2026-10-01 00:33:15 | AL41: 2026-10-05 10:08:40 | AM41: 6336 | AN41: =IF(X41="",0,1) -> 1 | AO41: =IF(AI41="",0,1) -> 1 | AP41: =DATE(YEAR(AE41),MONTH(AE41),DAY(AE41)) -> 46296 | AQ41: =IF(COUNTIF('同场线路Rotas do mesmo SC'!A:A,C41)>0,"Sim","Não") -> Não | AR41: =IF(COUNTIF(揽收业务网点!A:A,P41)>0,"Sim","Não") -> Sim
A42: SRTR22605709851 | B42: Concluído：已完成 | C42: M209-RBP-2000-1 | D42: Horário padrão | E42: Coleta | F42: 1 | G42: 328 | H42: BAG0F98 | I42: 3/4 | J42: WILIAN CARLOS DE OLIVEIRA | K42: Transportadora-三方 | L42: WILIAN | M42: JOSE NARCISO DIAS JUNIOR | N42: 11996257659 | O42: 535104 | P42: EXT -MG | Q42: MG | R42: 1692 | S42: 1691 | T42: 2026-09-30 18:32:53 | U42: 2026-09-30 18:58:12 | V42: 26 | W42: Não | X42: 2026-09-30 19:08:57 | Y42: 2026-09-30 20:00:00 | Z42: 2026-09-30 18:31:57 | AA42: 2026-09-30 18:31:57 | AB42: 31901 | AC42: SP RBP | AD42: SPN | AE42: 2026-10-01 00:48:00 | AF42: 2026-09-30 23:26:20 | AG42: -81 | AH42: 2026-09-30 23:26:20 | AI42: 2026-10-01 01:09:49 | AJ42: 105 | AK42: 2026-10-01 01:10:22 | AL42: 2026-10-01 06:07:35 | AM42: 298 | AN42: =IF(X42="",0,1) -> 1 | AO42: =IF(AI42="",0,1) -> 1 | AP42: =DATE(YEAR(AE42),MONTH(AE42),DAY(AE42)) -> 46296 | AQ42: =IF(COUNTIF('同场线路Rotas do mesmo SC'!A:A,C42)>0,"Sim","Não") -> Não | AR42: =IF(COUNTIF(揽收业务网点!A:A,P42)>0,"Sim","Não") -> Sim
...

Sheet 集货封车LACRE-COLETA
A1: 集货支线封车率-10.04 Taxa de lacramento secundária-Coleta | H1: 46299
A2: 序号Nº | B2: 发车区域 Região Saída | C2: 应封车 Lacre previsto | D2: 实际封车 Lacre realizado | E2: 封车率 taxa de lacre | F2: 目标 Meta | G2: 排名 Ranking
A3: 合计 | B3: 合计 | C3: =SUM(C4:C11) -> 33 | D3: =SUM(D4:D11) -> 30 | E3: =IFERROR((D3/C3),0) -> 0.90909091 | F3: 0.95 | G3: -
A4: =ROW()-3 -> 1 | B4: RJ | C4: =COUNTIFS(支线运输综合报表!Q:Q,B4,支线运输综合报表!AP:AP,$H$1,支线运输综合报表!E:E,"COLETA") -> 3 | D4: =SUMIFS(支线运输综合报表!AN:AN,支线运输综合报表!Q:Q,B4,支线运输综合报表!AP:AP,$H$1,支线运输综合报表!E:E,"COLETA") -> 3 | E4: =IFERROR((D4/C4),0) -> 1 | F4: 0.95 | G4: =RANK(E4,$E$4:$E$11) -> 1
A5: =ROW()-3 -> 2 | B5: MG | C5: =COUNTIFS(支线运输综合报表!Q:Q,B5,支线运输综合报表!AP:AP,$H$1,支线运输综合报表!E:E,"COLETA") -> 5 | D5: =SUMIFS(支线运输综合报表!AN:AN,支线运输综合报表!Q:Q,B5,支线运输综合报表!AP:AP,$H$1,支线运输综合报表!E:E,"COLETA") -> 5 | E5: =IFERROR((D5/C5),0) -> 1 | F5: 0.95 | G5: =RANK(E5,$E$4:$E$11) -> 1
A6: =ROW()-3 -> 3 | B6: SPN | C6: =COUNTIFS(支线运输综合报表!Q:Q,B6,支线运输综合报表!AP:AP,$H$1,支线运输综合报表!E:E,"COLETA") -> 9 | D6: =SUMIFS(支线运输综合报表!AN:AN,支线运输综合报表!Q:Q,B6,支线运输综合报表!AP:AP,$H$1,支线运输综合报表!E:E,"COLETA") -> 9 | E6: =IFERROR((D6/C6),0) -> 1 | F6: 0.95 | G6: =RANK(E6,$E$4:$E$11) -> 1
A7: =ROW()-3 -> 4 | B7: GP | C7: =COUNTIFS(支线运输综合报表!Q:Q,B7,支线运输综合报表!AP:AP,$H$1,支线运输综合报表!E:E,"COLETA") -> 1 | D7: =SUMIFS(支线运输综合报表!AN:AN,支线运输综合报表!Q:Q,B7,支线运输综合报表!AP:AP,$H$1,支线运输综合报表!E:E,"COLETA") -> 1 | E7: =IFERROR((D7/C7),0) -> 1 | F7: 0.95 | G7: =RANK(E7,$E$4:$E$11) -> 1
A8: =ROW()-3 -> 5 | B8: SPS | C8: =COUNTIFS(支线运输综合报表!Q:Q,B8,支线运输综合报表!AP:AP,$H$1,支线运输综合报表!E:E,"COLETA") -> 9 | D8: =SUMIFS(支线运输综合报表!AN:AN,支线运输综合报表!Q:Q,B8,支线运输综合报表!AP:AP,$H$1,支线运输综合报表!E:E,"COLETA") -> 8 | E8: =IFERROR((D8/C8),0) -> 0.88888889 | F8: 0.95 | G8: =RANK(E8,$E$4:$E$11) -> 5
A9: =ROW()-3 -> 6 | B9: SPE | C9: =COUNTIFS(支线运输综合报表!Q:Q,B9,支线运输综合报表!AP:AP,$H$1,支线运输综合报表!E:E,"COLETA") -> 4 | D9: =SUMIFS(支线运输综合报表!AN:AN,支线运输综合报表!Q:Q,B9,支线运输综合报表!AP:AP,$H$1,支线运输综合报表!E:E,"COLETA") -> 3 | E9: =IFERROR((D9/C9),0) -> 0.75 | F9: 0.95 | G9: =RANK(E9,$E$4:$E$11) -> 6
A10: =ROW()-3 -> 7 | B10: PR | C10: =COUNTIFS(支线运输综合报表!Q:Q,B10,支线运输综合报表!AP:AP,$H$1,支线运输综合报表!E:E,"COLETA") -> 2 | D10: =SUMIFS(支线运输综合报表!AN:AN,支线运输综合报表!Q:Q,B10,支线运输综合报表!AP:AP,$H$1,支线运输综合报表!E:E,"COLETA") -> 1 | E10: =IFERROR((D10/C10),0) -> 0.5 | F10: 0.95 | G10: =RANK(E10,$E$4:$E$11) -> 7
A11: =ROW()-3 -> 8 | B11: CE | C11: =COUNTIFS(支线运输综合报表!Q:Q,B11,支线运输综合报表!AP:AP,$H$1,支线运输综合报表!E:E,"COLETA") -> 0 | D11: =SUMIFS(支线运输综合报表!AN:AN,支线运输综合报表!Q:Q,B11,支线运输综合报表!AP:AP,$H$1,支线运输综合报表!E:E,"COLETA") -> 0 | E11: =IFERROR((D11/C11),0) -> 0 | F11: 0.95 | G11: =RANK(E11,$E$4:$E$11) -> 8
A12: 备注：每个任务单实际封车次数/应该封车次数 数据源：JMS-运力平台-支线运输综合报表-封签信息 时间：T-2，计划到达时间00-23:59:59 Obs:Número real delacre por ordem de tarefa / número previsto de lacre. Fonte: JMS – Plataforma de Capacidade – Relatório Geral de Transporte Secundário – Informação de Lacre. Período: T-2, considerando o horário planejado de chegada das 00:00 às 23:59:59.

Sheet 集货解车DESLACRE-COLETA
A1: 集货支线解车率-10.04 Taxa de deslacramento secundária-Coleta | H1: 46299
A2: 序号Nº | B2: 到车区域Região chegada | C2: 应解车Deslacre previsto | D2: 实际解车Deslacre realizado | E2: 解车率Taxa de deslacre | F2: 目标 Meta | G2: 排名 Ranking
A3: 合计 | B3: 合计 | C3: =SUM(C4:C12) -> 33 | D3: =SUM(D4:D12) -> 30 | E3: =D3/C3 -> 0.90909091 | F3: 0.9 | G3: -
A4: =ROW()-3 -> 1 | B4: RJ | C4: =COUNTIFS(支线运输综合报表!AD:AD,B4,支线运输综合报表!AP:AP,$H$1,支线运输综合报表!E:E,"COLETA") -> 3 | D4: =SUMIFS(支线运输综合报表!AO:AO,支线运输综合报表!AD:AD,B4,支线运输综合报表!AP:AP,$H$1,支线运输综合报表!E:E,"COLETA") -> 3 | E4: =IFERROR(D4/C4,0) -> 1 | F4: 0.9 | G4: =RANK(E4,$E$4:$E$12) -> 1
A5: =ROW()-3 -> 2 | B5: SPS | C5: =COUNTIFS(支线运输综合报表!AD:AD,B5,支线运输综合报表!AP:AP,$H$1,支线运输综合报表!E:E,"COLETA") -> 13 | D5: =SUMIFS(支线运输综合报表!AO:AO,支线运输综合报表!AD:AD,B5,支线运输综合报表!AP:AP,$H$1,支线运输综合报表!E:E,"COLETA") -> 13 | E5: =IFERROR(D5/C5,0) -> 1 | F5: 0.9 | G5: =RANK(E5,$E$4:$E$12) -> 1
A6: =ROW()-3 -> 3 | B6: MG | C6: =COUNTIFS(支线运输综合报表!AD:AD,B6,支线运输综合报表!AP:AP,$H$1,支线运输综合报表!E:E,"COLETA") -> 2 | D6: =SUMIFS(支线运输综合报表!AO:AO,支线运输综合报表!AD:AD,B6,支线运输综合报表!AP:AP,$H$1,支线运输综合报表!E:E,"COLETA") -> 2 | E6: =IFERROR(D6/C6,0) -> 1 | F6: 0.9 | G6: =RANK(E6,$E$4:$E$12) -> 1
A7: =ROW()-3 -> 4 | B7: GP | C7: =COUNTIFS(支线运输综合报表!AD:AD,B7,支线运输综合报表!AP:AP,$H$1,支线运输综合报表!E:E,"COLETA") -> 1 | D7: =SUMIFS(支线运输综合报表!AO:AO,支线运输综合报表!AD:AD,B7,支线运输综合报表!AP:AP,$H$1,支线运输综合报表!E:E,"COLETA") -> 1 | E7: =IFERROR(D7/C7,0) -> 1 | F7: 0.9 | G7: =RANK(E7,$E$4:$E$12) -> 1
A8: =ROW()-3 -> 5 | B8: SPN | C8: =COUNTIFS(支线运输综合报表!AD:AD,B8,支线运输综合报表!AP:AP,$H$1,支线运输综合报表!E:E,"COLETA") -> 9 | D8: =SUMIFS(支线运输综合报表!AO:AO,支线运输综合报表!AD:AD,B8,支线运输综合报表!AP:AP,$H$1,支线运输综合报表!E:E,"COLETA") -> 8 | E8: =IFERROR(D8/C8,0) -> 0.88888889 | F8: 0.9 | G8: =RANK(E8,$E$4:$E$12) -> 5
A9: =ROW()-3 -> 6 | B9: SPE | C9: =COUNTIFS(支线运输综合报表!AD:AD,B9,支线运输综合报表!AP:AP,$H$1,支线运输综合报表!E:E,"COLETA") -> 3 | D9: =SUMIFS(支线运输综合报表!AO:AO,支线运输综合报表!AD:AD,B9,支线运输综合报表!AP:AP,$H$1,支线运输综合报表!E:E,"COLETA") -> 2 | E9: =IFERROR(D9/C9,0) -> 0.66666667 | F9: 0.9 | G9: =RANK(E9,$E$4:$E$12) -> 6
A10: =ROW()-3 -> 7 | B10: PR | C10: =COUNTIFS(支线运输综合报表!AD:AD,B10,支线运输综合报表!AP:AP,$H$1,支线运输综合报表!E:E,"COLETA") -> 2 | D10: =SUMIFS(支线运输综合报表!AO:AO,支线运输综合报表!AD:AD,B10,支线运输综合报表!AP:AP,$H$1,支线运输综合报表!E:E,"COLETA") -> 1 | E10: =IFERROR(D10/C10,0) -> 0.5 | F10: 0.9 | G10: =RANK(E10,$E$4:$E$12) -> 7
A11: =ROW()-3 -> 8 | B11: CE | C11: =COUNTIFS(支线运输综合报表!AD:AD,B11,支线运输综合报表!AP:AP,$H$1,支线运输综合报表!E:E,"COLETA") -> 0 | D11: =SUMIFS(支线运输综合报表!AO:AO,支线运输综合报表!AD:AD,B11,支线运输综合报表!AP:AP,$H$1,支线运输综合报表!E:E,"COLETA") -> 0 | E11: =IFERROR(D11/C11,0) -> 0 | F11: 0.9 | G11: =RANK(E11,$E$4:$E$12) -> 8
A12: =ROW()-3 -> 9 | B12: BA | C12: =COUNTIFS(支线运输综合报表!AD:AD,B12,支线运输综合报表!AP:AP,$H$1,支线运输综合报表!E:E,"COLETA") -> 0 | D12: =SUMIFS(支线运输综合报表!AO:AO,支线运输综合报表!AD:AD,B12,支线运输综合报表!AP:AP,$H$1,支线运输综合报表!E:E,"COLETA") -> 0 | E12: =IFERROR(D12/C12,0) -> 0 | F12: 0.9 | G12: =RANK(E12,$E$4:$E$12) -> 8
A13: 备注：每个任务单实际解车次数/应该解车次数 数据源：JMS-运力平台-支线运输综合报表-解封信息 时间：T-2，计划到达时间00-23:59:59 Observação: Número real de deslacre por ordem de tarefa / número previsto de deslacre. Fonte:JMS – Plataforma de Capacidade – Relatório Geral de Transporte Secundário – Informação de Deslacração. Período: T-2, considerando o horário planejado de chegada das 00:00 às 23:59:59.

Sheet 散货封车LACRE-ENTEGA
A1: 散货支线封车率-10.04 Taxa de lacramento secundária-Entrega | H1: 46299
A2: 序号Nº | B2: 发车区域 Região Saída | C2: 应封车 Lacre previsto | D2: 实际封车 Lacre realizado | E2: 封车率 taxa de lacre | F2: 目标 Meta | G2: 排名 Ranking
A3: 合计 | B3: 合计 | C3: =SUM(C4:C12) -> 542 | D3: =SUM(D4:D12) -> 525 | E3: =D3/C3 -> 0.96863469 | F3: 0.95 | G3: -
A4: =ROW()-3 -> 1 | B4: SPN | C4: =COUNTIFS(支线运输综合报表!Q:Q,B4,支线运输综合报表!AP:AP,$H$1,支线运输综合报表!E:E,"ENTREGA") -> 78 | D4: =SUMIFS(支线运输综合报表!AN:AN,支线运输综合报表!Q:Q,B4,支线运输综合报表!AP:AP,$H$1,支线运输综合报表!E:E,"ENTREGA") -> 78 | E4: =D4/C4 -> 1 | F4: 0.95 | G4: =RANK(E4,$E$4:$E$12) -> 1
A5: =ROW()-3 -> 2 | B5: BA | C5: =COUNTIFS(支线运输综合报表!Q:Q,B5,支线运输综合报表!AP:AP,$H$1,支线运输综合报表!E:E,"ENTREGA") -> 17 | D5: =SUMIFS(支线运输综合报表!AN:AN,支线运输综合报表!Q:Q,B5,支线运输综合报表!AP:AP,$H$1,支线运输综合报表!E:E,"ENTREGA") -> 17 | E5: =D5/C5 -> 1 | F5: 0.95 | G5: =RANK(E5,$E$4:$E$12) -> 1
A6: =ROW()-3 -> 3 | B6: CE | C6: =COUNTIFS(支线运输综合报表!Q:Q,B6,支线运输综合报表!AP:AP,$H$1,支线运输综合报表!E:E,"ENTREGA") -> 7 | D6: =SUMIFS(支线运输综合报表!AN:AN,支线运输综合报表!Q:Q,B6,支线运输综合报表!AP:AP,$H$1,支线运输综合报表!E:E,"ENTREGA") -> 7 | E6: =D6/C6 -> 1 | F6: 0.95 | G6: =RANK(E6,$E$4:$E$12) -> 1
A7: =ROW()-3 -> 4 | B7: SPS | C7: =COUNTIFS(支线运输综合报表!Q:Q,B7,支线运输综合报表!AP:AP,$H$1,支线运输综合报表!E:E,"ENTREGA") -> 93 | D7: =SUMIFS(支线运输综合报表!AN:AN,支线运输综合报表!Q:Q,B7,支线运输综合报表!AP:AP,$H$1,支线运输综合报表!E:E,"ENTREGA") -> 92 | E7: =D7/C7 -> 0.98924731 | F7: 0.95 | G7: =RANK(E7,$E$4:$E$12) -> 4
A8: =ROW()-3 -> 5 | B8: GP | C8: =COUNTIFS(支线运输综合报表!Q:Q,B8,支线运输综合报表!AP:AP,$H$1,支线运输综合报表!E:E,"ENTREGA") -> 137 | D8: =SUMIFS(支线运输综合报表!AN:AN,支线运输综合报表!Q:Q,B8,支线运输综合报表!AP:AP,$H$1,支线运输综合报表!E:E,"ENTREGA") -> 134 | E8: =D8/C8 -> 0.97810219 | F8: 0.95 | G8: =RANK(E8,$E$4:$E$12) -> 5
A9: =ROW()-3 -> 6 | B9: RJ | C9: =COUNTIFS(支线运输综合报表!Q:Q,B9,支线运输综合报表!AP:AP,$H$1,支线运输综合报表!E:E,"ENTREGA") -> 35 | D9: =SUMIFS(支线运输综合报表!AN:AN,支线运输综合报表!Q:Q,B9,支线运输综合报表!AP:AP,$H$1,支线运输综合报表!E:E,"ENTREGA") -> 34 | E9: =D9/C9 -> 0.97142857 | F9: 0.95 | G9: =RANK(E9,$E$4:$E$12) -> 6
A10: =ROW()-3 -> 7 | B10: MG | C10: =COUNTIFS(支线运输综合报表!Q:Q,B10,支线运输综合报表!AP:AP,$H$1,支线运输综合报表!E:E,"ENTREGA") -> 75 | D10: =SUMIFS(支线运输综合报表!AN:AN,支线运输综合报表!Q:Q,B10,支线运输综合报表!AP:AP,$H$1,支线运输综合报表!E:E,"ENTREGA") -> 72 | E10: =D10/C10 -> 0.96 | F10: 0.95 | G10: =RANK(E10,$E$4:$E$12) -> 7
A11: =ROW()-3 -> 8 | B11: SPE | C11: =COUNTIFS(支线运输综合报表!Q:Q,B11,支线运输综合报表!AP:AP,$H$1,支线运输综合报表!E:E,"ENTREGA") -> 23 | D11: =SUMIFS(支线运输综合报表!AN:AN,支线运输综合报表!Q:Q,B11,支线运输综合报表!AP:AP,$H$1,支线运输综合报表!E:E,"ENTREGA") -> 21 | E11: =D11/C11 -> 0.91304348 | F11: 0.95 | G11: =RANK(E11,$E$4:$E$12) -> 8
A12: =ROW()-3 -> 9 | B12: PR | C12: =COUNTIFS(支线运输综合报表!Q:Q,B12,支线运输综合报表!AP:AP,$H$1,支线运输综合报表!E:E,"ENTREGA") -> 77 | D12: =SUMIFS(支线运输综合报表!AN:AN,支线运输综合报表!Q:Q,B12,支线运输综合报表!AP:AP,$H$1,支线运输综合报表!E:E,"ENTREGA") -> 70 | E12: =D12/C12 -> 0.90909091 | F12: 0.95 | G12: =RANK(E12,$E$4:$E$12) -> 9
A13: 备注：每个任务单实际封车次数/应该封车次数 数据源：JMS-运力平台-支线运输综合报表-封签信息 时间：T-2，计划到达时间00-23:59:59 Obs:Número real delacre por ordem de tarefa / número previsto de lacre. Fonte: JMS – Plataforma de Capacidade – Relatório Geral de Transporte Secundário – Informação de Lacre. Período: T-2, considerando o horário planejado de chegada das 00:00 às 23:59:59.

Sheet 散货解车DESLACRE-ENTREGA
A1: 散货支线解车率-10.04 Taxa de deslacramento secundária-Entrega | H1: 46299
A2: 序号Nº | B2: 到车区域Região chegada | C2: 应解车Deslacre previsto | D2: 实际解车Deslacre realizado | E2: 解车率Taxa de deslacre | F2: 目标 Meta | G2: 排名 Ranking
A3: 合计 | B3: 合计 | C3: =SUM(C4:C12) -> 542 | D3: =SUM(D4:D12) -> 490 | E3: =D3/C3 -> 0.90405904 | F3: 0.9 | G3: -
A4: =ROW()-3 -> 1 | B4: BA | C4: =COUNTIFS(支线运输综合报表!AD:AD,B4,支线运输综合报表!AP:AP,$H$1,支线运输综合报表!E:E,"ENTREGA") -> 17 | D4: =SUMIFS(支线运输综合报表!AO:AO,支线运输综合报表!AD:AD,B4,支线运输综合报表!AP:AP,$H$1,支线运输综合报表!E:E,"ENTREGA") -> 17 | E4: =D4/C4 -> 1 | F4: 0.9 | G4: =RANK(E4,$E$4:$E$12) -> 1
A5: =ROW()-3 -> 2 | B5: SPN | C5: =COUNTIFS(支线运输综合报表!AD:AD,B5,支线运输综合报表!AP:AP,$H$1,支线运输综合报表!E:E,"ENTREGA") -> 65 | D5: =SUMIFS(支线运输综合报表!AO:AO,支线运输综合报表!AD:AD,B5,支线运输综合报表!AP:AP,$H$1,支线运输综合报表!E:E,"ENTREGA") -> 63 | E5: =D5/C5 -> 0.96923077 | F5: 0.9 | G5: =RANK(E5,$E$4:$E$12) -> 2
A6: =ROW()-3 -> 3 | B6: MG | C6: =COUNTIFS(支线运输综合报表!AD:AD,B6,支线运输综合报表!AP:AP,$H$1,支线运输综合报表!E:E,"ENTREGA") -> 93 | D6: =SUMIFS(支线运输综合报表!AO:AO,支线运输综合报表!AD:AD,B6,支线运输综合报表!AP:AP,$H$1,支线运输综合报表!E:E,"ENTREGA") -> 87 | E6: =D6/C6 -> 0.93548387 | F6: 0.9 | G6: =RANK(E6,$E$4:$E$12) -> 3
A7: =ROW()-3 -> 4 | B7: SPS | C7: =COUNTIFS(支线运输综合报表!AD:AD,B7,支线运输综合报表!AP:AP,$H$1,支线运输综合报表!E:E,"ENTREGA") -> 87 | D7: =SUMIFS(支线运输综合报表!AO:AO,支线运输综合报表!AD:AD,B7,支线运输综合报表!AP:AP,$H$1,支线运输综合报表!E:E,"ENTREGA") -> 80 | E7: =D7/C7 -> 0.91954023 | F7: 0.9 | G7: =RANK(E7,$E$4:$E$12) -> 4
A8: =ROW()-3 -> 5 | B8: GP | C8: =COUNTIFS(支线运输综合报表!AD:AD,B8,支线运输综合报表!AP:AP,$H$1,支线运输综合报表!E:E,"ENTREGA") -> 135 | D8: =SUMIFS(支线运输综合报表!AO:AO,支线运输综合报表!AD:AD,B8,支线运输综合报表!AP:AP,$H$1,支线运输综合报表!E:E,"ENTREGA") -> 123 | E8: =D8/C8 -> 0.91111111 | F8: 0.9 | G8: =RANK(E8,$E$4:$E$12) -> 5
A9: =ROW()-3 -> 6 | B9: RJ | C9: =COUNTIFS(支线运输综合报表!AD:AD,B9,支线运输综合报表!AP:AP,$H$1,支线运输综合报表!E:E,"ENTREGA") -> 35 | D9: =SUMIFS(支线运输综合报表!AO:AO,支线运输综合报表!AD:AD,B9,支线运输综合报表!AP:AP,$H$1,支线运输综合报表!E:E,"ENTREGA") -> 30 | E9: =D9/C9 -> 0.85714286 | F9: 0.9 | G9: =RANK(E9,$E$4:$E$12) -> 6
A10: =ROW()-3 -> 7 | B10: PR | C10: =COUNTIFS(支线运输综合报表!AD:AD,B10,支线运输综合报表!AP:AP,$H$1,支线运输综合报表!E:E,"ENTREGA") -> 77 | D10: =SUMIFS(支线运输综合报表!AO:AO,支线运输综合报表!AD:AD,B10,支线运输综合报表!AP:AP,$H$1,支线运输综合报表!E:E,"ENTREGA") -> 64 | E10: =D10/C10 -> 0.83116883 | F10: 0.9 | G10: =RANK(E10,$E$4:$E$12) -> 7
A11: =ROW()-3 -> 8 | B11: SPE | C11: =COUNTIFS(支线运输综合报表!AD:AD,B11,支线运输综合报表!AP:AP,$H$1,支线运输综合报表!E:E,"ENTREGA") -> 26 | D11: =SUMIFS(支线运输综合报表!AO:AO,支线运输综合报表!AD:AD,B11,支线运输综合报表!AP:AP,$H$1,支线运输综合报表!E:E,"ENTREGA") -> 21 | E11: =D11/C11 -> 0.80769231 | F11: 0.9 | G11: =RANK(E11,$E$4:$E$12) -> 8
A12: =ROW()-3 -> 9 | B12: CE | C12: =COUNTIFS(支线运输综合报表!AD:AD,B12,支线运输综合报表!AP:AP,$H$1,支线运输综合报表!E:E,"ENTREGA") -> 7 | D12: =SUMIFS(支线运输综合报表!AO:AO,支线运输综合报表!AD:AD,B12,支线运输综合报表!AP:AP,$H$1,支线运输综合报表!E:E,"ENTREGA") -> 5 | E12: =D12/C12 -> 0.71428571 | F12: 0.9 | G12: =RANK(E12,$E$4:$E$12) -> 9
A13: 备注：每个任务单实际解车次数/应该解车次数 数据源：JMS-运力平台-支线运输综合报表-解封信息 时间：T-2，计划到达时间00-23:59:59 Observação: Número real de deslacre por ordem de tarefa / número previsto de deslacre. Fonte:JMS – Plataforma de Capacidade – Relatório Geral de Transporte Secundário – Informação de Deslacração. Período: T-2, considerando o horário planejado de chegada das 00:00 às 23:59:59.

Sheet 封车趋势Tendencia lacre
A1: 集货封车率趋势Tendência da LACRE-COLETA
A2: 发车区域Região de Saída | B2: 环比Variação± | C2: 10月累计Acumulado de Outubro | D2: 46296 | E2: =D2+1 -> 46297 | F2: =E2+1 -> 46298 | G2: =F2+1 -> 46299 | H2: =G2+1 -> 46300 | I2: =H2+1 -> 46301 | J2: =I2+1 -> 46302 | K2: =J2+1 -> 46303 | L2: =K2+1 -> 46304 | ... AH2: =AG2+1 -> 46326 | AI2: 近七天趋势
A3: 合计 | B3: =G3-F3 -> -0.015327696 | C3: =IFERROR(SUMIFS(支线运输综合报表!$AN:$AN,支线运输综合报表!$E:$E,"Coleta")/COUNTIFS(支线运输综合报表!$E:$E,"Coleta"),0) -> 0.94461078 | D3: =IFERROR(SUMIFS(支线运输综合报表!$AN:$AN,支线运输综合报表!$AP:$AP,D2,支线运输综合报表!$E:$E,"Coleta")/COUNTIFS(支线运输综合报表!$AP:$AP,D2,支线运输综合报表!$E:$E,"Coleta"),0) -> 0.95217391 | E3: =IFERROR(SUMIFS(支线运输综合报表!$AN:$AN,支线运输综合报表!$AP:$AP,E2,支线运输综合报表!$E:$E,"Coleta")/COUNTIFS(支线运输综合报表!$AP:$AP,E2,支线运输综合报表!$E:$E,"Coleta"),0) -> 0.95708155 | F3: =IFERROR(SUMIFS(支线运输综合报表!$AN:$AN,支线运输综合报表!$AP:$AP,F2,支线运输综合报表!$E:$E,"Coleta")/COUNTIFS(支线运输综合报表!$AP:$AP,F2,支线运输综合报表!$E:$E,"Coleta"),0) -> 0.9244186 | G3: =IFERROR(SUMIFS(支线运输综合报表!$AN:$AN,支线运输综合报表!$AP:$AP,G2,支线运输综合报表!$E:$E,"Coleta")/COUNTIFS(支线运输综合报表!$AP:$AP,G2,支线运输综合报表!$E:$E,"Coleta"),0) -> 0.90909091 | H3: =IFERROR(SUMIFS(支线运输综合报表!$AN:$AN,支线运输综合报表!$AP:$AP,H2,支线运输综合报表!$E:$E,"Coleta")/COUNTIFS(支线运输综合报表!$AP:$AP,H2,支线运输综合报表!$E:$E,"Coleta"),0) -> 0 | I3: =IFERROR(SUMIFS(支线运输综合报表!$AN:$AN,支线运输综合报表!$AP:$AP,I2,支线运输综合报表!$E:$E,"Coleta")/COUNTIFS(支线运输综合报表!$AP:$AP,I2,支线运输综合报表!$E:$E,"Coleta"),0) -> 0 | J3: =IFERROR(SUMIFS(支线运输综合报表!$AN:$AN,支线运输综合报表!$AP:$AP,J2,支线运输综合报表!$E:$E,"Coleta")/COUNTIFS(支线运输综合报表!$AP:$AP,J2,支线运输综合报表!$E:$E,"Coleta"),0) -> 0 | K3: =IFERROR(SUMIFS(支线运输综合报表!$AN:$AN,支线运输综合报表!$AP:$AP,K2,支线运输综合报表!$E:$E,"Coleta")/COUNTIFS(支线运输综合报表!$AP:$AP,K2,支线运输综合报表!$E:$E,"Coleta"),0) -> 0 | ... AH3: =IFERROR(SUMIFS(支线运输综合报表!$AN:$AN,支线运输综合报表!$AP:$AP,AH2,支线运输综合报表!$E:$E,"Coleta")/COUNTIFS(支线运输综合报表!$AP:$AP,AH2,支线运输综合报表!$E:$E,"Coleta"),0) -> 0
A4: SPN | B4: =G4-F4 -> 0.027777778 | C4: =IFERROR(SUMIFS(支线运输综合报表!$AN:$AN,支线运输综合报表!$Q:$Q,$A4,支线运输综合报表!$E:$E,"Coleta")/COUNTIFS(支线运输综合报表!$Q:$Q,$A4,支线运输综合报表!$E:$E,"Coleta"),0) -> 0.97247706 | D4: =IFERROR(SUMIFS(支线运输综合报表!$AN:$AN,支线运输综合报表!$Q:$Q,$A4,支线运输综合报表!$AP:$AP,D$2,支线运输综合报表!$E:$E,"Coleta")/COUNTIFS(支线运输综合报表!$Q:$Q,$A4,支线运输综合报表!$AP:$AP,D$2,支线运输综合报表!$E:$E,"Coleta"),0) -> 1 | E4: =IFERROR(SUMIFS(支线运输综合报表!$AN:$AN,支线运输综合报表!$Q:$Q,$A4,支线运输综合报表!$AP:$AP,E$2,支线运输综合报表!$E:$E,"Coleta")/COUNTIFS(支线运输综合报表!$Q:$Q,$A4,支线运输综合报表!$AP:$AP,E$2,支线运输综合报表!$E:$E,"Coleta"),0) -> 0.9375 | F4: =IFERROR(SUMIFS(支线运输综合报表!$AN:$AN,支线运输综合报表!$Q:$Q,$A4,支线运输综合报表!$AP:$AP,F$2,支线运输综合报表!$E:$E,"Coleta")/COUNTIFS(支线运输综合报表!$Q:$Q,$A4,支线运输综合报表!$AP:$AP,F$2,支线运输综合报表!$E:$E,"Coleta"),0) -> 0.97222222 | G4: =IFERROR(SUMIFS(支线运输综合报表!$AN:$AN,支线运输综合报表!$Q:$Q,$A4,支线运输综合报表!$AP:$AP,G$2,支线运输综合报表!$E:$E,"Coleta")/COUNTIFS(支线运输综合报表!$Q:$Q,$A4,支线运输综合报表!$AP:$AP,G$2,支线运输综合报表!$E:$E,"Coleta"),0) -> 1 | H4: =IFERROR(SUMIFS(支线运输综合报表!$AN:$AN,支线运输综合报表!$Q:$Q,$A4,支线运输综合报表!$AP:$AP,H$2,支线运输综合报表!$E:$E,"Coleta")/COUNTIFS(支线运输综合报表!$Q:$Q,$A4,支线运输综合报表!$AP:$AP,H$2,支线运输综合报表!$E:$E,"Coleta"),0) -> 0 | I4: =IFERROR(SUMIFS(支线运输综合报表!$AN:$AN,支线运输综合报表!$Q:$Q,$A4,支线运输综合报表!$AP:$AP,I$2,支线运输综合报表!$E:$E,"Coleta")/COUNTIFS(支线运输综合报表!$Q:$Q,$A4,支线运输综合报表!$AP:$AP,I$2,支线运输综合报表!$E:$E,"Coleta"),0) -> 0 | J4: =IFERROR(SUMIFS(支线运输综合报表!$AN:$AN,支线运输综合报表!$Q:$Q,$A4,支线运输综合报表!$AP:$AP,J$2,支线运输综合报表!$E:$E,"Coleta")/COUNTIFS(支线运输综合报表!$Q:$Q,$A4,支线运输综合报表!$AP:$AP,J$2,支线运输综合报表!$E:$E,"Coleta"),0) -> 0 | K4: =IFERROR(SUMIFS(支线运输综合报表!$AN:$AN,支线运输综合报表!$Q:$Q,$A4,支线运输综合报表!$AP:$AP,K$2,支线运输综合报表!$E:$E,"Coleta")/COUNTIFS(支线运输综合报表!$Q:$Q,$A4,支线运输综合报表!$AP:$AP,K$2,支线运输综合报表!$E:$E,"Coleta"),0) -> 0 | ... AH4: =IFERROR(SUMIFS(支线运输综合报表!$AN:$AN,支线运输综合报表!$Q:$Q,$A4,支线运输综合报表!$AP:$AP,AH$2,支线运输综合报表!$E:$E,"Coleta")/COUNTIFS(支线运输综合报表!$Q:$Q,$A4,支线运输综合报表!$AP:$AP,AH$2,支线运输综合报表!$E:$E,"Coleta"),0) -> 0
A5: SPS | B5: =G5-F5 -> -0.070570571 | C5: =IFERROR(SUMIFS(支线运输综合报表!$AN:$AN,支线运输综合报表!$Q:$Q,$A5,支线运输综合报表!$E:$E,"Coleta")/COUNTIFS(支线运输综合报表!$Q:$Q,$A5,支线运输综合报表!$E:$E,"Coleta"),0) -> 0.96226415 | D5: =IFERROR(SUMIFS(支线运输综合报表!$AN:$AN,支线运输综合报表!$Q:$Q,$A5,支线运输综合报表!$AP:$AP,D$2,支线运输综合报表!$E:$E,"Coleta")/COUNTIFS(支线运输综合报表!$Q:$Q,$A5,支线运输综合报表!$AP:$AP,D$2,支线运输综合报表!$E:$E,"Coleta"),0) -> 0.95726496 | E5: =IFERROR(SUMIFS(支线运输综合报表!$AN:$AN,支线运输综合报表!$Q:$Q,$A5,支线运输综合报表!$AP:$AP,E$2,支线运输综合报表!$E:$E,"Coleta")/COUNTIFS(支线运输综合报表!$Q:$Q,$A5,支线运输综合报表!$AP:$AP,E$2,支线运输综合报表!$E:$E,"Coleta"),0) -> 0.97457627 | F5: =IFERROR(SUMIFS(支线运输综合报表!$AN:$AN,支线运输综合报表!$Q:$Q,$A5,支线运输综合报表!$AP:$AP,F$2,支线运输综合报表!$E:$E,"Coleta")/COUNTIFS(支线运输综合报表!$Q:$Q,$A5,支线运输综合报表!$AP:$AP,F$2,支线运输综合报表!$E:$E,"Coleta"),0) -> 0.95945946 | G5: =IFERROR(SUMIFS(支线运输综合报表!$AN:$AN,支线运输综合报表!$Q:$Q,$A5,支线运输综合报表!$AP:$AP,G$2,支线运输综合报表!$E:$E,"Coleta")/COUNTIFS(支线运输综合报表!$Q:$Q,$A5,支线运输综合报表!$AP:$AP,G$2,支线运输综合报表!$E:$E,"Coleta"),0) -> 0.88888889 | H5: =IFERROR(SUMIFS(支线运输综合报表!$AN:$AN,支线运输综合报表!$Q:$Q,$A5,支线运输综合报表!$AP:$AP,H$2,支线运输综合报表!$E:$E,"Coleta")/COUNTIFS(支线运输综合报表!$Q:$Q,$A5,支线运输综合报表!$AP:$AP,H$2,支线运输综合报表!$E:$E,"Coleta"),0) -> 0 | I5: =IFERROR(SUMIFS(支线运输综合报表!$AN:$AN,支线运输综合报表!$Q:$Q,$A5,支线运输综合报表!$AP:$AP,I$2,支线运输综合报表!$E:$E,"Coleta")/COUNTIFS(支线运输综合报表!$Q:$Q,$A5,支线运输综合报表!$AP:$AP,I$2,支线运输综合报表!$E:$E,"Coleta"),0) -> 0 | J5: =IFERROR(SUMIFS(支线运输综合报表!$AN:$AN,支线运输综合报表!$Q:$Q,$A5,支线运输综合报表!$AP:$AP,J$2,支线运输综合报表!$E:$E,"Coleta")/COUNTIFS(支线运输综合报表!$Q:$Q,$A5,支线运输综合报表!$AP:$AP,J$2,支线运输综合报表!$E:$E,"Coleta"),0) -> 0 | K5: =IFERROR(SUMIFS(支线运输综合报表!$AN:$AN,支线运输综合报表!$Q:$Q,$A5,支线运输综合报表!$AP:$AP,K$2,支线运输综合报表!$E:$E,"Coleta")/COUNTIFS(支线运输综合报表!$Q:$Q,$A5,支线运输综合报表!$AP:$AP,K$2,支线运输综合报表!$E:$E,"Coleta"),0) -> 0 | ... AH5: =IFERROR(SUMIFS(支线运输综合报表!$AN:$AN,支线运输综合报表!$Q:$Q,$A5,支线运输综合报表!$AP:$AP,AH$2,支线运输综合报表!$E:$E,"Coleta")/COUNTIFS(支线运输综合报表!$Q:$Q,$A5,支线运输综合报表!$AP:$AP,AH$2,支线运输综合报表!$E:$E,"Coleta"),0) -> 0
